Workbook

Sheet Q3任务监控表
A1: 本季度天数 | B1: 92 | C1: 时间进度差 | D1: 预警颜色 | E1: 时间进度差 | F1: 预警颜色
A2: 已过天数 | B2: =COUNTIFS(消费汇总!B7:B96,">0") -> 0 | C2: 0%-10% | E2: 20%-30%
A3: 剩余天数 | B3: =B1-B2 -> 92 | C3: 10%-20% | E3: >30%
A4: 地区 | B4: 考核指标 | C4: 季度任务值 | D4: QTD完成 | E4: QTD完成率 | F4: 近七天日均 | G4: 日均差额 | H4: 预估完成率 | I4: 时间进度差
A5: 易尔通 | B5: 总包消费 | D5: =消费汇总!B3 | E5: =IF(C5="","-",D5/C5) -> - | F5: =SUM(OFFSET(消费汇总!B7,COUNT(消费汇总!B7:B96,">=0")-1,,-7,))/7 -> #REF! | G5: =IF(C5="","",(C5-D5)/$B$3-F5) | H5: =IF(C5="","-",(F5*$B$3+D5)/C5) -> - | I5: =IF(C5="","",E5-$B$2/$B$1)
B6: 大搜消费 | D6: =消费汇总!C3 | E6: =IF(C6="","-",D6/C6) -> - | F6: =SUM(OFFSET(消费汇总!C7,COUNT(消费汇总!C7:C96,">=0")-1,,-7,))/7 -> #REF! | G6: =IF(C6="","",(C6-D6)/$B$3-F6) | H6: =IF(C6="","-",(F6*$B$3+D6)/C6) -> - | I6: =IF(C6="","",E6-$B$2/$B$1)
B7: 信息流消费 | D7: =消费汇总!D3 | E7: =IF(C7="","-",D7/C7) -> - | F7: =SUM(OFFSET(消费汇总!D7,COUNT(消费汇总!D7:D96,">=0")-1,,-7,))/7 -> #REF! | G7: =IF(C7="","",(C7-D7)/$B$3-F7) | H7: =IF(C7="","-",(F7*$B$3+D7)/C7) -> - | I7: =IF(C7="","",E7-$B$2/$B$1)
B8: 潜力行业消费 | D8: =潜力行业!B3 | E8: =IF(C8="","-",D8/C8) -> - | F8: =SUM(OFFSET(潜力行业!B7,COUNT(潜力行业!B7:B96,">=0")-1,,-7,))/7 -> #REF! | G8: =IF(C8="","",(C8-D8)/$B$3-F8) | H8: =IF(C8="","-",(F8*$B$3+D8)/C8) -> - | I8: =IF(C8="","",E8-$B$2/$B$1)
B9: 二级地市消费-整体 | D9: =SUM(D10:D12) -> 0 | E9: =IF(C9="","-",D9/C9) -> - | F9: =SUM(F10:F12) -> 0 | G9: =IF(C9="","",(C9-D9)/$B$3-F9) | H9: =IF(C9="","-",(F9*$B$3+D9)/C9) -> - | I9: =IF(C9="","",E9-$B$2/$B$1)
B10: 泉州市 | D10: =二级地市消费汇总!L4 -> 0 | E10: =IF(C10="","-",D10/C10) -> - | F10: =SUM(OFFSET(二级地市消费汇总!L8,COUNT(二级地市消费汇总!L8:L97,">=0")-1,,-7,))/7 -> 0 | G10: =IF(C10="","",(C10-D10)/$B$3-F10) | H10: =IF(C10="","-",(F10*$B$3+D10)/C10) -> - | I10: =IF(C10="","",E10-$B$2/$B$1)
B11: 漳州市 | D11: =二级地市消费汇总!V4 -> 0 | E11: =IF(C11="","-",D11/C11) -> - | F11: =SUM(OFFSET(二级地市消费汇总!V8,COUNT(二级地市消费汇总!V8:V97,">=0")-1,,-7,))/7 -> 0 | G11: =IF(C11="","",(C11-D11)/$B$3-F11) | H11: =IF(C11="","-",(F11*$B$3+D11)/C11) -> - | I11: =IF(C11="","",E11-$B$2/$B$1)
B12: 龙岩市 | D12: =二级地市消费汇总!AF4 -> 0 | E12: =IF(C12="","-",D12/C12) -> - | F12: =SUM(OFFSET(二级地市消费汇总!AF8,COUNT(二级地市消费汇总!AF8:AF97,">=0")-1,,-7,))/7 -> 0 | G12: =IF(C12="","",(C12-D12)/$B$3-F12) | H12: =IF(C12="","-",(F12*$B$3+D12)/C12) -> - | I12: =IF(C12="","",E12-$B$2/$B$1)
A15: 地区 | B15: 考核指标 | C15: 季度任务值 | D15: QTD完成 | E15: QTD完成率 | F15: 近七天日均 | G15: 日均差额 | H15: 预估完成率 | I15: 时间进度差 | K15: 地区 | L15: 考核指标 | M15: 季度任务值 | N15: QTD完成 | O15: QTD完成率 | P15: 近七天日均 | Q15: 日均差额 | R15: 预估完成率 | S15: 时间进度差
A16: 厦门(企业) | B16: 总包消费 | D16: =二级地市消费汇总!C4 -> 0 | E16: =IF(C16="","-",D16/C16) -> - | F16: =SUM(OFFSET(二级地市消费汇总!C8,COUNTIF(二级地市消费汇总!C8:C97,">0")-1,0,-7,1))/7 -> 0 | G16: =IF(C16="","",(C16-D16)/$B$3-F16) | H16: =IF(C16="","-",(F16*$B$3+D16)/C16) -> - | I16: =IF(C16="","",E16-$B$2/$B$1) | K16: 泉州(企业) | L16: 总包消费 | N16: =二级地市消费汇总!M4 -> 0 | O16: =IF(M16="","-",N16/M16) -> - | P16: =SUM(OFFSET(二级地市消费汇总!M8,COUNTIF(二级地市消费汇总!M8:M97,">0")-1,0,-7,1))/7 -> 0 | Q16: =IF(M16="","",(M16-N16)/$B$3-P16) | R16: =IF(M16="","-",(P16*$B$3+N16)/M16) -> - | S16: =IF(M16="","",O16-$B$2/$B$1)
B17: 大搜消费 | D17: =二级地市消费汇总!D4 -> 0 | E17: =IF(C17="","-",D17/C17) -> - | F17: =SUM(OFFSET(二级地市消费汇总!D8,COUNT(二级地市消费汇总!D8:D97,">=0")-1,,-7,))/7 -> 0 | G17: =IF(C17="","",(C17-D17)/$B$3-F17) | H17: =IF(C17="","-",(F17*$B$3+D17)/C17) -> - | I17: =IF(C17="","",E17-$B$2/$B$1) | L17: 大搜消费 | N17: =二级地市消费汇总!N4 -> 0 | O17: =IF(M17="","-",N17/M17) -> - | P17: =SUM(OFFSET(二级地市消费汇总!N8,COUNT(二级地市消费汇总!N8:N97,">=0")-1,,-7,))/7 -> 0 | Q17: =IF(M17="","",(M17-N17)/$B$3-P17) | R17: =IF(M17="","-",(P17*$B$3+N17)/M17) -> - | S17: =IF(M17="","",O17-$B$2/$B$1)
B18: 信息流消费 | D18: =二级地市消费汇总!E4 -> 0 | E18: =IF(C18="","-",D18/C18) -> - | F18: =SUM(OFFSET(二级地市消费汇总!E8,COUNTIF(二级地市消费汇总!E8:E97,">0")-1,0,-7,1))/7 -> 0 | G18: =IF(C18="","",(C18-D18)/$B$3-F18) | H18: =IF(C18="","-",(F18*$B$3+D18)/C18) -> - | I18: =IF(C18="","",E18-$B$2/$B$1) | L18: 信息流消费 | N18: =二级地市消费汇总!O4 -> 0 | O18: =IF(M18="","-",N18/M18) -> - | P18: =SUM(OFFSET(二级地市消费汇总!O8,COUNTIF(二级地市消费汇总!O8:O97,">0")-1,0,-7,1))/7 -> 0 | Q18: =IF(M18="","",(M18-N18)/$B$3-P18) | R18: =IF(M18="","-",(P18*$B$3+N18)/M18) -> - | S18: =IF(M18="","",O18-$B$2/$B$1)
B19: 非医疗消费 | D19: =二级地市消费汇总!F4 -> 0 | E19: =IF(C19="","-",D19/C19) -> - | F19: =SUM(OFFSET(二级地市消费汇总!F8,COUNTIF(二级地市消费汇总!F8:F97,">0")-1,0,-7,1))/7 -> 0 | G19: =IF(C19="","",(C19-D19)/$B$3-F19) | H19: =IF(C19="","-",(F19*$B$3+D19)/C19) -> - | I19: =IF(C19="","",E19-$B$2/$B$1) | L19: 非医疗消费 | N19: =二级地市消费汇总!P4 -> 0 | O19: =IF(M19="","-",N19/M19) -> - | P19: =SUM(OFFSET(二级地市消费汇总!P8,COUNTIF(二级地市消费汇总!P8:P97,">0")-1,0,-7,1))/7 -> 0 | Q19: =IF(M19="","",(M19-N19)/$B$3-P19) | R19: =IF(M19="","-",(P19*$B$3+N19)/M19) -> - | S19: =IF(M19="","",O19-$B$2/$B$1)
B20: 医疗消费 | D20: =二级地市消费汇总!G4 -> 0 | E20: =IF(C20="","-",D20/C20) -> - | F20: =SUM(OFFSET(二级地市消费汇总!G8,COUNTIF(二级地市消费汇总!G8:G97,">0")-1,0,-7,1))/7 -> 0 | G20: =IF(C20="","",(C20-D20)/$B$3-F20) | H20: =IF(C20="","-",(F20*$B$3+D20)/C20) -> - | I20: =IF(C20="","",E20-$B$2/$B$1) | L20: 医疗消费 | N20: =二级地市消费汇总!Q4 -> 0 | O20: =IF(M20="","-",N20/M20) -> - | P20: =SUM(OFFSET(二级地市消费汇总!Q8,COUNTIF(二级地市消费汇总!Q8:Q97,">0")-1,0,-7,1))/7 -> 0 | Q20: =IF(M20="","",(M20-N20)/$B$3-P20) | R20: =IF(M20="","-",(P20*$B$3+N20)/M20) -> - | S20: =IF(M20="","",O20-$B$2/$B$1)
A22: 地区 | B22: 考核指标 | C22: 季度任务值 | D22: QTD完成 | E22: QTD完成率 | F22: 近七天日均 | G22: 日均差额 | H22: 预估完成率 | I22: 时间进度差 | K22: 地区 | L22: 考核指标 | M22: 季度任务值 | N22: QTD完成 | O22: QTD完成率 | P22: 近七天日均 | Q22: 日均差额 | R22: 预估完成率 | S22: 时间进度差
A23: 漳州(企业) | B23: 总包消费 | D23: =二级地市消费汇总!W4 -> 0 | E23: =IF(C23="","-",D23/C23) -> - | F23: =SUM(OFFSET(二级地市消费汇总!W8,COUNTIF(二级地市消费汇总!W8:W97,">0")-1,0,-7,1))/7 -> 0 | G23: =IF(C23="","",(C23-D23)/$B$3-F23) | H23: =IF(C23="","-",(F23*$B$3+D23)/C23) -> - | I23: =IF(C23="","",E23-$B$2/$B$1) | K23: 龙岩(企业) | L23: 总包消费 | N23: =二级地市消费汇总!AG4 -> 0 | O23: =IF(M23="","-",N23/M23) -> - | P23: =SUM(OFFSET(二级地市消费汇总!AG8,COUNTIF(二级地市消费汇总!AF8:AF97,">0")-1,0,-7,1))/7 -> 0 | Q23: =IF(M23="","",(M23-N23)/$B$3-P23) | R23: =IF(M23="","-",(P23*$B$3+N23)/M23) -> - | S23: =IF(M23="","",O23-$B$2/$B$1)
B24: 大搜消费 | D24: =二级地市消费汇总!X4 -> 0 | E24: =IF(C24="","-",D24/C24) -> - | F24: =SUM(OFFSET(二级地市消费汇总!X8,COUNT(二级地市消费汇总!X8:X97,">0")-1,,-7,))/7 -> 0 | G24: =IF(C24="","",(C24-D24)/$B$3-F24) | H24: =IF(C24="","-",(F24*$B$3+D24)/C24) -> - | I24: =IF(C24="","",E24-$B$2/$B$1) | L24: 大搜消费 | N24: =二级地市消费汇总!AH4 -> 0 | O24: =IF(M24="","-",N24/M24) -> - | P24: =SUM(OFFSET(二级地市消费汇总!AH8,COUNT(二级地市消费汇总!AH8:AH97,">=0")-1,,-7,))/7 -> 0 | Q24: =IF(M24="","",(M24-N24)/$B$3-P24) | R24: =IF(M24="","-",(P24*$B$3+N24)/M24) -> - | S24: =IF(M24="","",O24-$B$2/$B$1)
B25: 信息流消费 | D25: =二级地市消费汇总!Y4 -> 0 | E25: =IF(C25="","-",D25/C25) -> - | F25: =SUM(OFFSET(二级地市消费汇总!Y8,COUNTIF(二级地市消费汇总!Y8:Y97,">0")-1,0,-7,1))/7 -> 0 | G25: =IF(C25="","",(C25-D25)/$B$3-F25) | H25: =IF(C25="","-",(F25*$B$3+D25)/C25) -> - | I25: =IF(C25="","",E25-$B$2/$B$1) | L25: 信息流消费 | N25: =二级地市消费汇总!AI4 -> 0 | O25: =IF(M25="","-",N25/M25) -> - | P25: =SUM(OFFSET(二级地市消费汇总!AI8,COUNTIF(二级地市消费汇总!AI8:AI97,">0")-1,0,-7,1))/7 -> 0 | Q25: =IF(M25="","",(M25-N25)/$B$3-P25) | R25: =IF(M25="","-",(P25*$B$3+N25)/M25) -> - | S25: =IF(M25="","",O25-$B$2/$B$1)
B26: 非医疗消费 | D26: =二级地市消费汇总!Z5 | E26: =IF(C26="","-",D26/C26) -> - | F26: =SUM(OFFSET(二级地市消费汇总!Z8,COUNTIF(二级地市消费汇总!Z8:Z97,">0")-1,0,-7,1))/7 -> 0 | G26: =IF(C26="","",(C26-D26)/$B$3-F26) | H26: =IF(C26="","-",(F26*$B$3+D26)/C26) -> - | I26: =IF(C26="","",E26-$B$2/$B$1) | L26: 非医疗消费 | N26: =二级地市消费汇总!AJ4 -> 0 | O26: =IF(M26="","-",N26/M26) -> - | P26: =SUM(OFFSET(二级地市消费汇总!AJ8,COUNTIF(二级地市消费汇总!AJ8:AJ97,">0")-1,0,-7,1))/7 -> 0 | Q26: =IF(M26="","",(M26-N26)/$B$3-P26) | R26: =IF(M26="","-",(P26*$B$3+N26)/M26) -> - | S26: =IF(M26="","",O26-$B$2/$B$1)
B27: 医疗消费 | D27: =二级地市消费汇总!AA4 -> 0 | E27: =IF(C27="","-",D27/C27) -> - | F27: =SUM(OFFSET(二级地市消费汇总!AA8,COUNTIF(二级地市消费汇总!AA8:AA97,">0")-1,0,-7,1))/7 -> 0 | G27: =IF(C27="","",(C27-D27)/$B$3-F27) | H27: =IF(C27="","-",(F27*$B$3+D27)/C27) -> - | I27: =IF(C27="","",E27-$B$2/$B$1) | L27: 医疗消费 | N27: =二级地市消费汇总!AK4 -> 0 | O27: =IF(M27="","-",N27/M27) -> - | P27: =SUM(OFFSET(二级地市消费汇总!AK8,COUNTIF(二级地市消费汇总!AK8:AK97,">0")-1,0,-7,1))/7 -> 0 | Q27: =IF(M27="","",(M27-N27)/$B$3-P27) | R27: =IF(M27="","-",(P27*$B$3+N27)/M27) -> - | S27: =IF(M27="","",O27-$B$2/$B$1)

Sheet 消费汇总
A1: 汇总（企业+框架） | B1: 总包 | C1: 大搜消费 | D1: 信息流消费 | E1: 医疗 | F1: 非医疗 | H1: 企业汇总 | I1: 总包 | K1: 大搜 | M1: 信息流 | O1: 医疗 | Q1: 非医疗 | S1: 品牌展示 | U1: 中小客户数QTD完成 | V1: 中小消费QTD完成 | X1: 框架汇总 | Y1: 总包 | Z1: 大搜消费 | AA1: 信息流消费 | AB1: 医疗 | AC1: 非医疗
I2: 消费 | J2: 有消费客户数 | K2: 消费 | L2: 有消费客户数 | M2: 消费 | N2: 有消费客户数 | O2: 消费 | P2: 有消费客户数 | Q2: 消费 | R2: 有消费客户数 | S2: 消费 | T2: 有消费客户数
A3: 2023Q3 | B3: =IF(B4="","",SUM(B4:B6)) | C3: =IF(C4="","",SUM(C4:C6)) | D3: =IF(D4="","",SUM(D4:D6)) | E3: =IF(E4="","",SUM(E4:E6)) | F3: =IF(F4="","",SUM(F4:F6)) | H3: 2023Q3 | I3: =IF(I4="","",SUM(I4:I6)) | J3: - | K3: =IF(K4="","",SUM(K4:K6)) | L3: - | M3: =IF(M4="","",SUM(M4:M6)) | N3: - | O3: =IF(O4="","",SUM(O4:O6)) | P3: - | Q3: =IF(Q4="","",SUM(Q4:Q6)) | R3: - | S3: =IF(S4="","",SUM(S4:S6)) | T3: - | U3: =MAX(U7:U96) -> 0 | V3: =MAX(V7:V96) -> 0 | X3: 2023Q3 | Y3: =IF(Y4="","",SUM(Y4:Y6)) | Z3: =IF(Z4="","",SUM(Z4:Z6)) | AA3: =IF(AA4="","",SUM(AA4:AA6)) | AB3: =IF(AB4="","",SUM(AB4:AB6)) | AC3: =IF(AC4="","",SUM(AC4:AC6))
A4: 7月份 | B4: =IF(B7="","",SUM(B7:B36)) | C4: =IF(C7="","",SUM(C7:C36)) | D4: =IF(D7="","",SUM(D7:D36)) | E4: =IF(E7="","",SUM(E7:E36)) | F4: =IF(F7="","",SUM(F7:F36)) | H4: 7月份 | I4: =IF(I7="","",SUM(I7:I36)) | J4: - | K4: =IF(K7="","",SUM(K7:K36)) | L4: - | M4: =IF(M7="","",SUM(M7:M36)) | N4: - | O4: =IF(O7="","",SUM(O7:O36)) | P4: - | Q4: =IF(Q7="","",SUM(Q7:Q36)) | R4: - | S4: =IF(S7="","",SUM(S7:S36)) | T4: - | U4: =IF(U7="","",MAX(U7:U37)) | V4: =IF(V7="","",MAX(V7:V37)) | X4: 7月份 | Y4: =IF(Y7="","",SUM(Y7:Y36)) | Z4: =IF(Z7="","",SUM(Z7:Z36)) | AA4: =IF(AA7="","",SUM(AA7:AA36)) | AB4: =IF(AB7="","",SUM(AB7:AB36)) | AC4: =IF(AC7="","",SUM(AC7:AC36))
A5: 8月份 | B5: =IF(B37="","",SUM(B37:B67)) | C5: =IF(C37="","",SUM(C37:C67)) | D5: =IF(D37="","",SUM(D37:D67)) | E5: =IF(E37="","",SUM(E37:E67)) | F5: =IF(F37="","",SUM(F37:F67)) | H5: 8月份 | I5: =IF(I37="","",SUM(I37:I67)) | J5: - | K5: =IF(K37="","",SUM(K37:K67)) | L5: - | M5: =IF(M37="","",SUM(M37:M67)) | N5: - | O5: =IF(O37="","",SUM(O37:O67)) | P5: - | Q5: =IF(Q37="","",SUM(Q37:Q67)) | R5: - | S5: =IF(S37="","",SUM(S37:S67)) | T5: - | U5: =IF(U38="","",MAX(U38:U65)) | V5: =IF(V38="","",MAX(V38:V65)) | X5: 8月份 | Y5: =IF(Y37="","",SUM(Y37:Y67)) | Z5: =IF(Z37="","",SUM(Z37:Z67)) | AA5: =IF(AA37="","",SUM(AA37:AA67)) | AB5: =IF(AB37="","",SUM(AB37:AB67)) | AC5: =IF(AC37="","",SUM(AC37:AC67))
A6: 9月份 | B6: =IF(B68="","",SUM(B68:B97)) | C6: =IF(C68="","",SUM(C68:C97)) | D6: =IF(D68="","",SUM(D68:D97)) | E6: =IF(E68="","",SUM(E68:E97)) | F6: =IF(F68="","",SUM(F68:F97)) | H6: 9月份 | I6: =IF(I68="","",SUM(I68:I97)) | J6: - | K6: =IF(K68="","",SUM(K68:K97)) | L6: - | M6: =IF(M68="","",SUM(M68:M97)) | N6: - | O6: =IF(O68="","",SUM(O68:O97)) | P6: - | Q6: =IF(Q68="","",SUM(Q68:Q97)) | R6: - | S6: =IF(S68="","",SUM(S68:S97)) | T6: - | U6: =IF(U66="","",MAX(U66:U96)) | V6: =IF(V66="","",MAX(V66:V96)) | X6: 9月份 | Y6: =IF(Y68="","",SUM(Y68:Y97)) | Z6: =IF(Z68="","",SUM(Z68:Z97)) | AA6: =IF(AA68="","",SUM(AA68:AA97)) | AB6: =IF(AB68="","",SUM(AB68:AB97)) | AC6: =IF(AC68="","",SUM(AC68:AC97))
A7: 45108 | H7: =A7 -> 45108 | X7: =H7 -> 45108
A8: 45109 | H8: =A8 -> 45109 | X8: =H8 -> 45109
A9: 45110 | H9: =A9 -> 45110 | X9: =H9 -> 45110
A10: 45111 | H10: =A10 -> 45111 | X10: =H10 -> 45111
A11: 45112 | H11: =A11 -> 45112 | X11: =H11 -> 45112
A12: 45113 | H12: =A12 -> 45113 | X12: =H12 -> 45113
A13: 45114 | H13: =A13 -> 45114 | X13: =H13 -> 45114
A14: 45115 | H14: =A14 -> 45115 | X14: =H14 -> 45115
A15: 45116 | H15: =A15 -> 45116 | X15: =H15 -> 45116
A16: 45117 | H16: =A16 -> 45117 | X16: =H16 -> 45117
A17: 45118 | H17: =A17 -> 45118 | X17: =H17 -> 45118
A18: 45119 | H18: =A18 -> 45119 | X18: =H18 -> 45119
... A98: 45199 | H98: =A98 -> 45199 | X98: =H98 -> 45199

Sheet 二级地市消费汇总
A1: 日期 | B1: 厦门市 | K1: 日期 | L1: 泉州市 | U1: 日期 | V1: 漳州市 | AE1: 日期 | AF1: 龙岩市
B2: 总包（企业+框架） | C2: 企业 | I2: 框架 | L2: 总包（企业+框架） | M2: 企业 | S2: 框架 | V2: 总包（企业+框架） | W2: 企业 | AC2: 框架 | AF2: 总包（企业+框架） | AG2: 企业 | AM2: 框架
C3: 总包 | D3: 大搜 | E3: 信息流 | F3: 医疗 | G3: 非医疗 | H3: 品牌展示 | M3: 总包 | N3: 大搜 | O3: 信息流 | P3: 医疗 | Q3: 非医疗 | R3: 品牌展示 | W3: 总包 | X3: 大搜 | Y3: 信息流 | Z3: 医疗 | AA3: 非医疗 | AB3: 品牌展示 | AG3: 总包 | AH3: 大搜 | AI3: 信息流 | AJ3: 医疗 | AK3: 非医疗 | AL3: 品牌展示
A4: 2023Q3 | B4: =SUM(B5:B7) -> 0 | C4: =SUM(C5:C7) -> 0 | D4: =SUM(D5:D7) -> 0 | E4: =SUM(E5:E7) -> 0 | F4: =SUM(F5:F7) -> 0 | G4: =SUM(G5:G7) -> 0 | H4: =SUM(H5:H7) -> 0 | I4: =SUM(I5:I7) -> 0 | K4: 2023Q3 | L4: =SUM(L5:L7) -> 0 | M4: =SUM(M5:M7) -> 0 | N4: =SUM(N5:N7) -> 0 | O4: =SUM(O5:O7) -> 0 | P4: =SUM(P5:P7) -> 0 | Q4: =SUM(Q5:Q7) -> 0 | R4: =SUM(R5:R7) -> 0 | S4: =SUM(S5:S7) -> 0 | U4: 2023Q3 | V4: =SUM(V5:V7) -> 0 | W4: =SUM(W5:W7) -> 0 | X4: =SUM(X5:X7) -> 0 | Y4: =SUM(Y5:Y7) -> 0 | Z4: =SUM(Z5:Z7) -> 0 | AA4: =SUM(AA5:AA7) -> 0 | AB4: =SUM(AB5:AB7) -> 0 | AC4: =SUM(AC5:AC7) -> 0 | AE4: 2023Q3 | AF4: =SUM(AF5:AF7) -> 0 | AG4: =SUM(AG5:AG7) -> 0 | AH4: =SUM(AH5:AH7) -> 0 | AI4: =SUM(AI5:AI7) -> 0 | AJ4: =SUM(AJ5:AJ7) -> 0 | AK4: =SUM(AK5:AK7) -> 0 | AL4: =SUM(AL5:AL7) -> 0 | AM4: =SUM(AM5:AM7) -> 0
A5: 7月份 | B5: =IF(B8="","",SUM(B8:B37)) | C5: =IF(C8="","",SUM(C8:C37)) | D5: =IF(D8="","",SUM(D8:D37)) | E5: =IF(E8="","",SUM(E8:E37)) | F5: =IF(F8="","",SUM(F8:F37)) | G5: =IF(G8="","",SUM(G8:G37)) | H5: =IF(H8="","",SUM(H8:H37)) | I5: =IF(I8="","",SUM(I8:I37)) | K5: 7月份 | L5: =IF(L8="","",SUM(L8:L37)) | M5: =IF(M8="","",SUM(M8:M37)) | N5: =IF(N8="","",SUM(N8:N37)) | O5: =IF(O8="","",SUM(O8:O37)) | P5: =IF(P8="","",SUM(P8:P37)) | Q5: =IF(Q8="","",SUM(Q8:Q37)) | R5: =IF(R8="","",SUM(R8:R37)) | S5: =IF(S8="","",SUM(S8:S37)) | U5: 7月份 | V5: =IF(V8="","",SUM(V8:V37)) | W5: =IF(W8="","",SUM(W8:W37)) | X5: =IF(X8="","",SUM(X8:X37)) | Y5: =IF(Y8="","",SUM(Y8:Y37)) | Z5: =IF(Z8="","",SUM(Z8:Z37)) | AA5: =IF(AA8="","",SUM(AA8:AA37)) | AB5: =IF(AB8="","",SUM(AB8:AB37)) | AC5: =IF(AC8="","",SUM(AC8:AC37)) | AE5: 7月份 | AF5: =IF(AF8="","",SUM(AF8:AF37)) | AG5: =IF(AG8="","",SUM(AG8:AG37)) | AH5: =IF(AH8="","",SUM(AH8:AH37)) | AI5: =IF(AI8="","",SUM(AI8:AI37)) | AJ5: =IF(AJ8="","",SUM(AJ8:AJ37)) | AK5: =IF(AK8="","",SUM(AK8:AK37)) | AL5: =IF(AL8="","",SUM(AL8:AL37)) | AM5: =IF(AM8="","",SUM(AM8:AM37))
A6: 8月份 | B6: =IF(B38="","",SUM(B38:B68)) | C6: =IF(C38="","",SUM(C38:C68)) | D6: =IF(D38="","",SUM(D38:D68)) | E6: =IF(E38="","",SUM(E38:E68)) | F6: =IF(F38="","",SUM(F38:F68)) | G6: =IF(G38="","",SUM(G38:G68)) | H6: =IF(H38="","",SUM(H38:H68)) | I6: =IF(I38="","",SUM(I38:I68)) | K6: 8月份 | L6: =IF(L38="","",SUM(L38:L68)) | M6: =IF(M38="","",SUM(M38:M68)) | N6: =IF(N38="","",SUM(N38:N68)) | O6: =IF(O38="","",SUM(O38:O68)) | P6: =IF(P38="","",SUM(P38:P68)) | Q6: =IF(Q38="","",SUM(Q38:Q68)) | R6: =IF(R38="","",SUM(R38:R68)) | S6: =IF(S38="","",SUM(S38:S68)) | U6: 8月份 | V6: =IF(V38="","",SUM(V38:V68)) | W6: =IF(W38="","",SUM(W38:W68)) | X6: =IF(X38="","",SUM(X38:X68)) | Y6: =IF(Y38="","",SUM(Y38:Y68)) | Z6: =IF(Z38="","",SUM(Z38:Z68)) | AA6: =IF(AA38="","",SUM(AA38:AA68)) | AB6: =IF(AB38="","",SUM(AB38:AB68)) | AC6: =IF(AC38="","",SUM(AC38:AC68)) | AE6: 8月份 | AF6: =IF(AF38="","",SUM(AF38:AF68)) | AG6: =IF(AG38="","",SUM(AG38:AG68)) | AH6: =IF(AH38="","",SUM(AH38:AH68)) | AI6: =IF(AI38="","",SUM(AI38:AI68)) | AJ6: =IF(AJ38="","",SUM(AJ38:AJ68)) | AK6: =IF(AK38="","",SUM(AK38:AK68)) | AL6: =IF(AL38="","",SUM(AL38:AL68)) | AM6: =IF(AM38="","",SUM(AM38:AM68))
A7: 9月份 | B7: =IF(B69="","",SUM(B69:B98)) | C7: =IF(C69="","",SUM(C69:C98)) | D7: =IF(D69="","",SUM(D69:D98)) | E7: =IF(E69="","",SUM(E69:E98)) | F7: =IF(F69="","",SUM(F69:F98)) | G7: =IF(G69="","",SUM(G69:G98)) | H7: =IF(H69="","",SUM(H69:H98)) | I7: =IF(I69="","",SUM(I69:I98)) | J7: =IF(J67="","",SUM(J67:J97)) | K7: 9月份 | L7: =IF(L69="","",SUM(L69:L98)) | M7: =IF(M69="","",SUM(M69:M98)) | N7: =IF(N69="","",SUM(N69:N98)) | O7: =IF(O69="","",SUM(O69:O98)) | P7: =IF(P69="","",SUM(P69:P98)) | Q7: =IF(Q69="","",SUM(Q69:Q98)) | R7: =IF(R69="","",SUM(R69:R98)) | S7: =IF(S69="","",SUM(S69:S98)) | U7: 9月份 | V7: =IF(V69="","",SUM(V69:V98)) | W7: =IF(W69="","",SUM(W69:W98)) | X7: =IF(X69="","",SUM(X69:X98)) | Y7: =IF(Y69="","",SUM(Y69:Y98)) | Z7: =IF(Z69="","",SUM(Z69:Z98)) | AA7: =IF(AA69="","",SUM(AA69:AA98)) | AB7: =IF(AB69="","",SUM(AB69:AB98)) | AC7: =IF(AC69="","",SUM(AC69:AC98)) | AE7: 9月份 | AF7: =IF(AF69="","",SUM(AF69:AF98)) | AG7: =IF(AG69="","",SUM(AG69:AG98)) | AH7: =IF(AH69="","",SUM(AH69:AH98)) | AI7: =IF(AI69="","",SUM(AI69:AI98)) | AJ7: =IF(AJ69="","",SUM(AJ69:AJ98)) | AK7: =IF(AK69="","",SUM(AK69:AK98)) | AL7: =IF(AL69="","",SUM(AL69:AL98)) | AM7: =IF(AM69="","",SUM(AM69:AM98))
A8: 45108 | K8: =A8 -> 45108 | U8: =K8 -> 45108 | AE8: =U8 -> 45108
A9: 45109 | K9: =A9 -> 45109 | U9: =K9 -> 45109 | AE9: =U9 -> 45109
A10: 45110 | K10: =A10 -> 45110 | U10: =K10 -> 45110 | AE10: =U10 -> 45110
A11: 45111 | K11: =A11 -> 45111 | U11: =K11 -> 45111 | AE11: =U11 -> 45111
A12: 45112 | K12: =A12 -> 45112 | U12: =K12 -> 45112 | AE12: =U12 -> 45112
A13: 45113 | K13: =A13 -> 45113 | U13: =K13 -> 45113 | AE13: =U13 -> 45113
A14: 45114 | K14: =A14 -> 45114 | U14: =K14 -> 45114 | AE14: =U14 -> 45114
A15: 45115 | K15: =A15 -> 45115 | U15: =K15 -> 45115 | AE15: =U15 -> 45115
A16: 45116 | K16: =A16 -> 45116 | U16: =K16 -> 45116 | AE16: =U16 -> 45116
A17: 45117 | K17: =A17 -> 45117 | U17: =K17 -> 45117 | AE17: =U17 -> 45117
A18: 45118 | K18: =A18 -> 45118 | U18: =K18 -> 45118 | AE18: =U18 -> 45118
A19: 45119 | K19: =A19 -> 45119 | U19: =K19 -> 45119 | AE19: =U19 -> 45119
... A99: 45199 | K99: =A99 -> 45199 | U99: =K99 -> 45199 | AE99: =U99 -> 45199

Sheet 新单数据
A1: 新单汇总 | B1: 合计 | C1: 厦门 | D1: 泉州 | E1: 漳州 | F1: 龙岩 | H1: 新单消费汇总 | I1: 合计 | J1: 厦门 | K1: 泉州 | L1: 漳州 | M1: 龙岩 | O1: 新单消费占比 | P1: 合计 | Q1: 厦门 | R1: 泉州 | S1: 漳州 | T1: 龙岩 | V1: 信息流新单数 | W1: 合计 | X1: 厦门 | Y1: 泉州 | Z1: 漳州 | AA1: 龙岩
A2: 2023Q3 | B2: =SUM(B6:B95) -> 0 | C2: =SUM(C6:C95) -> 0 | D2: =SUM(D6:D95) -> 0 | E2: =SUM(E6:E95) -> 0 | F2: =SUM(F6:F95) -> 0 | H2: 2023Q3 | I2: =SUM(I6:I95) -> 0 | J2: =SUM(J6:J95) -> 0 | K2: =SUM(K6:K95) -> 0 | L2: =SUM(L6:L95) -> 0 | M2: =SUM(M6:M95) -> 0 | O2: 2023Q3 | P2: =IF(I2="","",I2/消费汇总!I3) -> #VALUE! | Q2: =IF(J2="","",J2/二级地市消费汇总!C4) -> #DIV/0! | R2: =IF(K2="","",新单数据!K2/二级地市消费汇总!M4) -> #DIV/0! | S2: =IF(L2="","",L2/二级地市消费汇总!W4) -> #DIV/0! | T2: =IF(M2="","",M2/二级地市消费汇总!AG4) -> #DIV/0! | V2: 2023Q3 | W2: =SUM(W6:W95) -> 0 | X2: =SUM(X6:X95) -> 0 | Y2: =SUM(Y6:Y95) -> 0 | Z2: =SUM(Z6:Z95) -> 0 | AA2: =SUM(AA6:AA95) -> 0
A3: 7月份 | B3: =IF(B6="","",SUM(B6:B35)) | C3: =IF(C6="","",SUM(C6:C35)) | D3: =IF(D6="","",SUM(D6:D35)) | E3: =IF(E6="","",SUM(E6:E35)) | F3: =IF(F6="","",SUM(F6:F35)) | H3: 7月份 | I3: =IF(I6="","",SUM(I6:I35)) | J3: =IF(J6="","",SUM(J6:J35)) | K3: =IF(K6="","",SUM(K6:K35)) | L3: =IF(L6="","",SUM(L6:L35)) | M3: =IF(M6="","",SUM(M6:M35)) | O3: 7月份 | P3: =IF(I3="","",I3/消费汇总!I4) | Q3: =IF(J3="","",J3/二级地市消费汇总!C5) | R3: =IF(K3="","",新单数据!K3/二级地市消费汇总!M5) | S3: =IF(L3="","",L3/二级地市消费汇总!W5) | T3: =IF(M3="","",M3/二级地市消费汇总!AG5) | V3: 7月份 | W3: =IF(W6="","",SUM(W6:W35)) | X3: =IF(X6="","",SUM(X6:X35)) | Y3: =IF(Y6="","",SUM(Y6:Y35)) | Z3: =IF(Z6="","",SUM(Z6:Z35)) | AA3: =IF(AA6="","",SUM(AA6:AA35))
A4: 8月份 | B4: =IF(B36="","",SUM(B36:B66)) | C4: =IF(C36="","",SUM(C36:C66)) | D4: =IF(D36="","",SUM(D36:D66)) | E4: =IF(E36="","",SUM(E36:E66)) | F4: =IF(F36="","",SUM(F36:F66)) | H4: 8月份 | I4: =IF(I36="","",SUM(I36:I66)) | J4: =IF(J36="","",SUM(J36:J66)) | K4: =IF(K36="","",SUM(K36:K66)) | L4: =IF(L36="","",SUM(L36:L66)) | M4: =IF(M36="","",SUM(M36:M66)) | O4: 8月份 | P4: =IF(I4="","",I4/消费汇总!I5) | Q4: =IF(J4="","",J4/二级地市消费汇总!C6) | R4: =IF(K4="","",新单数据!K4/二级地市消费汇总!M6) | S4: =IF(L4="","",L4/二级地市消费汇总!W6) | T4: =IF(M4="","",M4/二级地市消费汇总!AG6) | V4: 8月份 | W4: =IF(W36="","",SUM(W36:W66)) | X4: =IF(X36="","",SUM(X36:X66)) | Y4: =IF(Y36="","",SUM(Y36:Y66)) | Z4: =IF(Z36="","",SUM(Z36:Z66)) | AA4: =IF(AA36="","",SUM(AA36:AA66))
A5: 9月份 | B5: =IF(B67="","",SUM(B67:B96)) | C5: =IF(C67="","",SUM(C67:C96)) | D5: =IF(D67="","",SUM(D67:D96)) | E5: =IF(E67="","",SUM(E67:E96)) | F5: =IF(F67="","",SUM(F67:F96)) | H5: 9月份 | I5: =IF(I67="","",SUM(I67:I96)) | J5: =IF(J67="","",SUM(J67:J96)) | K5: =IF(K67="","",SUM(K67:K96)) | L5: =IF(L67="","",SUM(L67:L96)) | M5: =IF(M67="","",SUM(M67:M96)) | O5: 9月份 | P5: =IF(I5="","",I5/消费汇总!I6) | Q5: =IF(J5="","",J5/二级地市消费汇总!C7) | R5: =IF(K5="","",新单数据!K5/二级地市消费汇总!M7) | S5: =IF(L5="","",L5/二级地市消费汇总!W7) | T5: =IF(M5="","",M5/二级地市消费汇总!AG7) | V5: 9月份 | W5: =IF(W67="","",SUM(W67:W96)) | X5: =IF(X67="","",SUM(X67:X96)) | Y5: =IF(Y67="","",SUM(Y67:Y96)) | Z5: =IF(Z67="","",SUM(Z67:Z96)) | AA5: =IF(AA67="","",SUM(AA67:AA96))
A6: 45108 | B6: =IF(C6="","",SUM(C6:F6)) | H6: =A6 -> 45108 | I6: =IF(J6="","",SUM(J6:M6)) | O6: =H6 -> 45108 | P6: =IF(I6="","",I6/消费汇总!I7) | Q6: =IF(J6="","",J6/二级地市消费汇总!C8) | R6: =IF(K6="","",新单数据!K6/二级地市消费汇总!M8) | S6: =IF(L6="","",L6/二级地市消费汇总!W8) | T6: =IF(M6="","",M6/二级地市消费汇总!AG8) | V6: =O6 -> 45108 | W6: =IF(X6="","",SUM(X6:AA6))
A7: 45109 | B7: =IF(C7="","",SUM(C7:F7)) | H7: =A7 -> 45109 | I7: =IF(J7="","",SUM(J7:M7)) | O7: =H7 -> 45109 | P7: =IF(I7="","",I7/消费汇总!I8) | Q7: =IF(J7="","",J7/二级地市消费汇总!C9) | R7: =IF(K7="","",新单数据!K7/二级地市消费汇总!M9) | S7: =IF(L7="","",L7/二级地市消费汇总!W9) | T7: =IF(M7="","",M7/二级地市消费汇总!AG9) | V7: =O7 -> 45109 | W7: =IF(X7="","",SUM(X7:AA7))
A8: 45110 | B8: =IF(C8="","",SUM(C8:F8)) | H8: =A8 -> 45110 | I8: =IF(J8="","",SUM(J8:M8)) | O8: =H8 -> 45110 | P8: =IF(I8="","",I8/消费汇总!I9) | Q8: =IF(J8="","",J8/二级地市消费汇总!C10) | R8: =IF(K8="","",新单数据!K8/二级地市消费汇总!M10) | S8: =IF(L8="","",L8/二级地市消费汇总!W10) | T8: =IF(M8="","",M8/二级地市消费汇总!AG10) | V8: =O8 -> 45110 | W8: =IF(X8="","",SUM(X8:AA8))
A9: 45111 | B9: =IF(C9="","",SUM(C9:F9)) | H9: =A9 -> 45111 | I9: =IF(J9="","",SUM(J9:M9)) | O9: =H9 -> 45111 | P9: =IF(I9="","",I9/消费汇总!I10) | Q9: =IF(J9="","",J9/二级地市消费汇总!C11) | R9: =IF(K9="","",新单数据!K9/二级地市消费汇总!M11) | S9: =IF(L9="","",L9/二级地市消费汇总!W11) | T9: =IF(M9="","",M9/二级地市消费汇总!AG11) | V9: =O9 -> 45111 | W9: =IF(X9="","",SUM(X9:AA9))
A10: 45112 | B10: =IF(C10="","",SUM(C10:F10)) | H10: =A10 -> 45112 | I10: =IF(J10="","",SUM(J10:M10)) | O10: =H10 -> 45112 | P10: =IF(I10="","",I10/消费汇总!I11) | Q10: =IF(J10="","",J10/二级地市消费汇总!C12) | R10: =IF(K10="","",新单数据!K10/二级地市消费汇总!M12) | S10: =IF(L10="","",L10/二级地市消费汇总!W12) | T10: =IF(M10="","",M10/二级地市消费汇总!AG12) | V10: =O10 -> 45112 | W10: =IF(X10="","",SUM(X10:AA10))
A11: 45113 | B11: =IF(C11="","",SUM(C11:F11)) | H11: =A11 -> 45113 | I11: =IF(J11="","",SUM(J11:M11)) | O11: =H11 -> 45113 | P11: =IF(I11="","",I11/消费汇总!I12) | Q11: =IF(J11="","",J11/二级地市消费汇总!C13) | R11: =IF(K11="","",新单数据!K11/二级地市消费汇总!M13) | S11: =IF(L11="","",L11/二级地市消费汇总!W13) | T11: =IF(M11="","",M11/二级地市消费汇总!AG13) | V11: =O11 -> 45113 | W11: =IF(X11="","",SUM(X11:AA11))
A12: 45114 | B12: =IF(C12="","",SUM(C12:F12)) | H12: =A12 -> 45114 | I12: =IF(J12="","",SUM(J12:M12)) | O12: =H12 -> 45114 | P12: =IF(I12="","",I12/消费汇总!I13) | Q12: =IF(J12="","",J12/二级地市消费汇总!C14) | R12: =IF(K12="","",新单数据!K12/二级地市消费汇总!M14) | S12: =IF(L12="","",L12/二级地市消费汇总!W14) | T12: =IF(M12="","",M12/二级地市消费汇总!AG14) | V12: =O12 -> 45114 | W12: =IF(X12="","",SUM(X12:AA12))
A13: 45115 | B13: =IF(C13="","",SUM(C13:F13)) | H13: =A13 -> 45115 | I13: =IF(J13="","",SUM(J13:M13)) | O13: =H13 -> 45115 | P13: =IF(I13="","",I13/消费汇总!I14) | Q13: =IF(J13="","",J13/二级地市消费汇总!C15) | R13: =IF(K13="","",新单数据!K13/二级地市消费汇总!M15) | S13: =IF(L13="","",L13/二级地市消费汇总!W15) | T13: =IF(M13="","",M13/二级地市消费汇总!AG15) | V13: =O13 -> 45115 | W13: =IF(X13="","",SUM(X13:AA13))
A14: 45116 | B14: =IF(C14="","",SUM(C14:F14)) | H14: =A14 -> 45116 | I14: =IF(J14="","",SUM(J14:M14)) | O14: =H14 -> 45116 | P14: =IF(I14="","",I14/消费汇总!I15) | Q14: =IF(J14="","",J14/二级地市消费汇总!C16) | R14: =IF(K14="","",新单数据!K14/二级地市消费汇总!M16) | S14: =IF(L14="","",L14/二级地市消费汇总!W16) | T14: =IF(M14="","",M14/二级地市消费汇总!AG16) | V14: =O14 -> 45116 | W14: =IF(X14="","",SUM(X14:AA14))
A15: 45117 | B15: =IF(C15="","",SUM(C15:F15)) | H15: =A15 -> 45117 | I15: =IF(J15="","",SUM(J15:M15)) | O15: =H15 -> 45117 | P15: =IF(I15="","",I15/消费汇总!I16) | Q15: =IF(J15="","",J15/二级地市消费汇总!C17) | R15: =IF(K15="","",新单数据!K15/二级地市消费汇总!M17) | S15: =IF(L15="","",L15/二级地市消费汇总!W17) | T15: =IF(M15="","",M15/二级地市消费汇总!AG17) | V15: =O15 -> 45117 | W15: =IF(X15="","",SUM(X15:AA15))
A16: 45118 | B16: =IF(C16="","",SUM(C16:F16)) | H16: =A16 -> 45118 | I16: =IF(J16="","",SUM(J16:M16)) | O16: =H16 -> 45118 | P16: =IF(I16="","",I16/消费汇总!I17) | Q16: =IF(J16="","",J16/二级地市消费汇总!C18) | R16: =IF(K16="","",新单数据!K16/二级地市消费汇总!M18) | S16: =IF(L16="","",L16/二级地市消费汇总!W18) | T16: =IF(M16="","",M16/二级地市消费汇总!AG18) | V16: =O16 -> 45118 | W16: =IF(X16="","",SUM(X16:AA16))
A17: 45119 | B17: =IF(C17="","",SUM(C17:F17)) | H17: =A17 -> 45119 | I17: =IF(J17="","",SUM(J17:M17)) | O17: =H17 -> 45119 | P17: =IF(I17="","",I17/消费汇总!I18) | Q17: =IF(J17="","",J17/二级地市消费汇总!C19) | R17: =IF(K17="","",新单数据!K17/二级地市消费汇总!M19) | S17: =IF(L17="","",L17/二级地市消费汇总!W19) | T17: =IF(M17="","",M17/二级地市消费汇总!AG19) | V17: =O17 -> 45119 | W17: =IF(X17="","",SUM(X17:AA17))
... A60: 45162 | B60: =IF(C60="","",SUM(C60:F60)) | H60: =A60 -> 45162 | I60: =IF(J60="","",SUM(J60:M60)) | O60: =H60 -> 45162 | P60: =IF(I60="","",I60/消费汇总!I61) | Q60: =IF(J60="","",J60/二级地市消费汇总!C62) | R60: =IF(K60="","",新单数据!K60/二级地市消费汇总!M62) | S60: =IF(L60="","",L60/二级地市消费汇总!W62) | T60: =IF(M60="","",M60/二级地市消费汇总!AG62) | V60: =O60 -> 45162 | W60: =IF(X60="","",SUM(X60:AA60))
A61: 45163 | B61: =IF(C61="","",SUM(C61:F61)) | H61: =A61 -> 45163 | I61: =IF(J61="","",SUM(J61:M61)) | O61: =H61 -> 45163 | P61: =IF(I61="","",I61/消费汇总!I62) | Q61: =IF(J61="","",J61/二级地市消费汇总!C63) | R61: =IF(K61="","",新单数据!K61/二级地市消费汇总!M63) | S61: =IF(L61="","",L61/二级地市消费汇总!W63) | T61: =IF(M61="","",M61/二级地市消费汇总!AG63) | V61: =O61 -> 45163 | W61: =IF(X61="","",SUM(X61:AA61)) | AB61: 0
A62: 45164 | B62: =IF(C62="","",SUM(C62:F62)) | H62: =A62 -> 45164 | I62: =IF(J62="","",SUM(J62:M62)) | O62: =H62 -> 45164 | P62: =IF(I62="","",I62/消费汇总!I63) | Q62: =IF(J62="","",J62/二级地市消费汇总!C64) | R62: =IF(K62="","",新单数据!K62/二级地市消费汇总!M64) | S62: =IF(L62="","",L62/二级地市消费汇总!W64) | T62: =IF(M62="","",M62/二级地市消费汇总!AG64) | V62: =O62 -> 45164 | W62: =IF(X62="","",SUM(X62:AA62))
A63: 45165 | B63: =IF(C63="","",SUM(C63:F63)) | H63: =A63 -> 45165 | I63: =IF(J63="","",SUM(J63:M63)) | O63: =H63 -> 45165 | P63: =IF(I63="","",I63/消费汇总!I64) | Q63: =IF(J63="","",J63/二级地市消费汇总!C65) | R63: =IF(K63="","",新单数据!K63/二级地市消费汇总!M65) | S63: =IF(L63="","",L63/二级地市消费汇总!W65) | T63: =IF(M63="","",M63/二级地市消费汇总!AG65) | V63: =O63 -> 45165 | W63: =IF(X63="","",SUM(X63:AA63))
A64: 45166 | B64: =IF(C64="","",SUM(C64:F64)) | H64: =A64 -> 45166 | I64: =IF(J64="","",SUM(J64:M64)) | O64: =H64 -> 45166 | P64: =IF(I64="","",I64/消费汇总!I65) | Q64: =IF(J64="","",J64/二级地市消费汇总!C66) | R64: =IF(K64="","",新单数据!K64/二级地市消费汇总!M66) | S64: =IF(L64="","",L64/二级地市消费汇总!W66) | T64: =IF(M64="","",M64/二级地市消费汇总!AG66) | V64: =O64 -> 45166 | W64: =IF(X64="","",SUM(X64:AA64))
A65: 45167 | B65: =IF(C65="","",SUM(C65:F65)) | H65: =A65 -> 45167 | I65: =IF(J65="","",SUM(J65:M65)) | O65: =H65 -> 45167 | P65: =IF(I65="","",I65/消费汇总!I66) | Q65: =IF(J65="","",J65/二级地市消费汇总!C67) | R65: =IF(K65="","",新单数据!K65/二级地市消费汇总!M67) | S65: =IF(L65="","",L65/二级地市消费汇总!W67) | T65: =IF(M65="","",M65/二级地市消费汇总!AG67) | V65: =O65 -> 45167 | W65: =IF(X65="","",SUM(X65:AA65))
A66: 45168 | B66: =IF(C66="","",SUM(C66:F66)) | H66: =A66 -> 45168 | I66: =IF(J66="","",SUM(J66:M66)) | O66: =H66 -> 45168 | P66: =IF(I66="","",I66/消费汇总!I67) | Q66: =IF(J66="","",J66/二级地市消费汇总!C68) | R66: =IF(K66="","",新单数据!K66/二级地市消费汇总!M68) | S66: =IF(L66="","",L66/二级地市消费汇总!W68) | T66: =IF(M66="","",M66/二级地市消费汇总!AG68) | V66: =O66 -> 45168 | W66: =IF(X66="","",SUM(X66:AA66))
A67: 45169 | B67: =IF(C67="","",SUM(C67:F67)) | H67: =A67 -> 45169 | I67: =IF(J67="","",SUM(J67:M67)) | O67: =H67 -> 45169 | P67: =IF(I67="","",I67/消费汇总!I68) | Q67: =IF(J67="","",J67/二级地市消费汇总!C69) | R67: =IF(K67="","",新单数据!K67/二级地市消费汇总!M69) | S67: =IF(L67="","",L67/二级地市消费汇总!W69) | T67: =IF(M67="","",M67/二级地市消费汇总!AG69) | V67: =O67 -> 45169 | W67: =IF(X67="","",SUM(X67:AA67))
A68: 45170 | B68: =IF(C68="","",SUM(C68:F68)) | H68: =A68 -> 45170 | I68: =IF(J68="","",SUM(J68:M68)) | O68: =H68 -> 45170 | P68: =IF(I68="","",I68/消费汇总!I69) | Q68: =IF(J68="","",J68/二级地市消费汇总!C70) | R68: =IF(K68="","",新单数据!K68/二级地市消费汇总!M70) | S68: =IF(L68="","",L68/二级地市消费汇总!W70) | T68: =IF(M68="","",M68/二级地市消费汇总!AG70) | V68: =O68 -> 45170 | W68: =IF(X68="","",SUM(X68:AA68))
A69: 45171 | B69: =IF(C69="","",SUM(C69:F69)) | H69: =A69 -> 45171 | I69: =IF(J69="","",SUM(J69:M69)) | O69: =H69 -> 45171 | P69: =IF(I69="","",I69/消费汇总!I70) | Q69: =IF(J69="","",J69/二级地市消费汇总!C71) | R69: =IF(K69="","",新单数据!K69/二级地市消费汇总!M71) | S69: =IF(L69="","",L69/二级地市消费汇总!W71) | T69: =IF(M69="","",M69/二级地市消费汇总!AG71) | V69: =O69 -> 45171 | W69: =IF(X69="","",SUM(X69:AA69))
A70: 45172 | B70: =IF(C70="","",SUM(C70:F70)) | H70: =A70 -> 45172 | I70: =IF(J70="","",SUM(J70:M70)) | O70: =H70 -> 45172 | P70: =IF(I70="","",I70/消费汇总!I71) | Q70: =IF(J70="","",J70/二级地市消费汇总!C72) | R70: =IF(K70="","",新单数据!K70/二级地市消费汇总!M72) | S70: =IF(L70="","",L70/二级地市消费汇总!W72) | T70: =IF(M70="","",M70/二级地市消费汇总!AG72) | V70: =O70 -> 45172 | W70: =IF(X70="","",SUM(X70:AA70))
A71: 45173 | B71: =IF(C71="","",SUM(C71:F71)) | H71: =A71 -> 45173 | I71: =IF(J71="","",SUM(J71:M71)) | O71: =H71 -> 45173 | P71: =IF(I71="","",I71/消费汇总!I72) | Q71: =IF(J71="","",J71/二级地市消费汇总!C73) | R71: =IF(K71="","",新单数据!K71/二级地市消费汇总!M73) | S71: =IF(L71="","",L71/二级地市消费汇总!W73) | T71: =IF(M71="","",M71/二级地市消费汇总!AG73) | V71: =O71 -> 45173 | W71: =IF(X71="","",SUM(X71:AA71))
A72: 45174 | B72: =IF(C72="","",SUM(C72:F72)) | H72: =A72 -> 45174 | I72: =IF(J72="","",SUM(J72:M72)) | O72: =H72 -> 45174 | P72: =IF(I72="","",I72/消费汇总!I73) | Q72: =IF(J72="","",J72/二级地市消费汇总!C74) | R72: =IF(K72="","",新单数据!K72/二级地市消费汇总!M74) | S72: =IF(L72="","",L72/二级地市消费汇总!W74) | T72: =IF(M72="","",M72/二级地市消费汇总!AG74) | V72: =O72 -> 45174 | W72: =IF(X72="","",SUM(X72:AA72))
A73: 45175 | B73: =IF(C73="","",SUM(C73:F73)) | H73: =A73 -> 45175 | I73: =IF(J73="","",SUM(J73:M73)) | O73: =H73 -> 45175 | P73: =IF(I73="","",I73/消费汇总!I74) | Q73: =IF(J73="","",J73/二级地市消费汇总!C75) | R73: =IF(K73="","",新单数据!K73/二级地市消费汇总!M75) | S73: =IF(L73="","",L73/二级地市消费汇总!W75) | T73: =IF(M73="","",M73/二级地市消费汇总!AG75) | V73: =O73 -> 45175 | W73: =IF(X73="","",SUM(X73:AA73))
... A78: 45180 | B78: =IF(C78="","",SUM(C78:F78)) | H78: =A78 -> 45180 | I78: =IF(J78="","",SUM(J78:M78)) | O78: =H78 -> 45180 | P78: =IF(I78="","",I78/消费汇总!I79) | Q78: =IF(J78="","",J78/二级地市消费汇总!C80) | R78: =IF(K78="","",新单数据!K78/二级地市消费汇总!M80) | S78: =IF(L78="","",L78/二级地市消费汇总!W80) | T78: =IF(M78="","",M78/二级地市消费汇总!AG80) | V78: =O78 -> 45180 | W78: =IF(X78="","",SUM(X78:AA78))
A79: 45181 | B79: =IF(C79="","",SUM(C79:F79)) | H79: =A79 -> 45181 | I79: =IF(J79="","",SUM(J79:M79)) | O79: =H79 -> 45181 | P79: =IF(I79="","",I79/消费汇总!I80) | Q79: =IF(J79="","",J79/二级地市消费汇总!C81) | R79: =IF(K79="","",新单数据!K79/二级地市消费汇总!M81) | S79: =IF(L79="","",L79/二级地市消费汇总!W81) | T79: =IF(M79="","",M79/二级地市消费汇总!AG81) | V79: =O79 -> 45181 | W79: =IF(X79="","",SUM(X79:AA79)) | AB79: 0
A80: 45182 | B80: =IF(C80="","",SUM(C80:F80)) | H80: =A80 -> 45182 | I80: =IF(J80="","",SUM(J80:M80)) | O80: =H80 -> 45182 | P80: =IF(I80="","",I80/消费汇总!I81) | Q80: =IF(J80="","",J80/二级地市消费汇总!C82) | R80: =IF(K80="","",新单数据!K80/二级地市消费汇总!M82) | S80: =IF(L80="","",L80/二级地市消费汇总!W82) | T80: =IF(M80="","",M80/二级地市消费汇总!AG82) | V80: =O80 -> 45182 | W80: =IF(X80="","",SUM(X80:AA80))
A81: 45183 | B81: =IF(C81="","",SUM(C81:F81)) | H81: =A81 -> 45183 | I81: =IF(J81="","",SUM(J81:M81)) | O81: =H81 -> 45183 | P81: =IF(I81="","",I81/消费汇总!I82) | Q81: =IF(J81="","",J81/二级地市消费汇总!C83) | R81: =IF(K81="","",新单数据!K81/二级地市消费汇总!M83) | S81: =IF(L81="","",L81/二级地市消费汇总!W83) | T81: =IF(M81="","",M81/二级地市消费汇总!AG83) | V81: =O81 -> 45183 | W81: =IF(X81="","",SUM(X81:AA81))
A82: 45184 | B82: =IF(C82="","",SUM(C82:F82)) | H82: =A82 -> 45184 | I82: =IF(J82="","",SUM(J82:M82)) | O82: =H82 -> 45184 | P82: =IF(I82="","",I82/消费汇总!I83) | Q82: =IF(J82="","",J82/二级地市消费汇总!C84) | R82: =IF(K82="","",新单数据!K82/二级地市消费汇总!M84) | S82: =IF(L82="","",L82/二级地市消费汇总!W84) | T82: =IF(M82="","",M82/二级地市消费汇总!AG84) | V82: =O82 -> 45184 | W82: =IF(X82="","",SUM(X82:AA82))
A83: 45185 | B83: =IF(C83="","",SUM(C83:F83)) | H83: =A83 -> 45185 | I83: =IF(J83="","",SUM(J83:M83)) | O83: =H83 -> 45185 | P83: =IF(I83="","",I83/消费汇总!I84) | Q83: =IF(J83="","",J83/二级地市消费汇总!C85) | R83: =IF(K83="","",新单数据!K83/二级地市消费汇总!M85) | S83: =IF(L83="","",L83/二级地市消费汇总!W85) | T83: =IF(M83="","",M83/二级地市消费汇总!AG85) | V83: =O83 -> 45185 | W83: =IF(X83="","",SUM(X83:AA83))
A84: 45186 | B84: =IF(C84="","",SUM(C84:F84)) | H84: =A84 -> 45186 | I84: =IF(J84="","",SUM(J84:M84)) | O84: =H84 -> 45186 | P84: =IF(I84="","",I84/消费汇总!I85) | Q84: =IF(J84="","",J84/二级地市消费汇总!C86) | R84: =IF(K84="","",新单数据!K84/二级地市消费汇总!M86) | S84: =IF(L84="","",L84/二级地市消费汇总!W86) | T84: =IF(M84="","",M84/二级地市消费汇总!AG86) | V84: =O84 -> 45186 | W84: =IF(X84="","",SUM(X84:AA84))
A85: 45187 | B85: =IF(C85="","",SUM(C85:F85)) | H85: =A85 -> 45187 | I85: =IF(J85="","",SUM(J85:M85)) | O85: =H85 -> 45187 | P85: =IF(I85="","",I85/消费汇总!I86) | Q85: =IF(J85="","",J85/二级地市消费汇总!C87) | R85: =IF(K85="","",新单数据!K85/二级地市消费汇总!M87) | S85: =IF(L85="","",L85/二级地市消费汇总!W87) | T85: =IF(M85="","",M85/二级地市消费汇总!AG87) | V85: =O85 -> 45187 | W85: =IF(X85="","",SUM(X85:AA85))
A86: 45188 | B86: =IF(C86="","",SUM(C86:F86)) | H86: =A86 -> 45188 | I86: =IF(J86="","",SUM(J86:M86)) | O86: =H86 -> 45188 | P86: =IF(I86="","",I86/消费汇总!I87) | Q86: =IF(J86="","",J86/二级地市消费汇总!C88) | R86: =IF(K86="","",新单数据!K86/二级地市消费汇总!M88) | S86: =IF(L86="","",L86/二级地市消费汇总!W88) | T86: =IF(M86="","",M86/二级地市消费汇总!AG88) | V86: =O86 -> 45188 | W86: =IF(X86="","",SUM(X86:AA86))
...

Sheet 潜力行业
A1: 潜力行业
B2: 整体消费 | C2: 口腔美容 | D2: 眼科美容 | E2: 职业培训 | F2: 装修建材 | G2: 装潢装修 | H2: 通用机械设备 | I2: 房地产开发商 | J2: 房产中介
A3: 2023Q3 | B3: =IF(B4="","",SUM(B4:B6)) | C3: =IF(C4="","",SUM(C4:C6)) | D3: =IF(D4="","",SUM(D4:D6)) | E3: =IF(E4="","",SUM(E4:E6)) | F3: =IF(F4="","",SUM(F4:F6)) | G3: =IF(G4="","",SUM(G4:G6)) | H3: =IF(H4="","",SUM(H4:H6)) | I3: =IF(I4="","",SUM(I4:I6)) | J3: =IF(J4="","",SUM(J4:J6))
A4: 7月份 | B4: =IF(B7="","",SUM(B7:B36)) | C4: =IF(C7="","",SUM(C7:C36)) | D4: =IF(D7="","",SUM(D7:D36)) | E4: =IF(E7="","",SUM(E7:E36)) | F4: =IF(F7="","",SUM(F7:F36)) | G4: =IF(G7="","",SUM(G7:G36)) | H4: =IF(H7="","",SUM(H7:H36)) | I4: =IF(I7="","",SUM(I7:I36)) | J4: =IF(J7="","",SUM(J7:J36))
A5: 8月份 | B5: =IF(B37="","",SUM(B37:B67)) | C5: =IF(C37="","",SUM(C37:C67)) | D5: =IF(D37="","",SUM(D37:D67)) | E5: =IF(E37="","",SUM(E37:E67)) | F5: =IF(F37="","",SUM(F37:F67)) | G5: =IF(G37="","",SUM(G37:G67)) | H5: =IF(H37="","",SUM(H37:H67)) | I5: =IF(I37="","",SUM(I37:I67)) | J5: =IF(J37="","",SUM(J37:J67))
A6: 9月份 | B6: =IF(B68="","",SUM(B68:B97)) | C6: =IF(C68="","",SUM(C68:C97)) | D6: =IF(D68="","",SUM(D68:D97)) | E6: =IF(E68="","",SUM(E68:E97)) | F6: =IF(F68="","",SUM(F68:F97)) | G6: =IF(G68="","",SUM(G68:G97)) | H6: =IF(H68="","",SUM(H68:H97)) | I6: =IF(I68="","",SUM(I68:I97)) | J6: =IF(J68="","",SUM(J68:J97))
A7: 45108
A8: 45109
A9: 45110
A10: 45111
A11: 45112
A12: 45113
A13: 45114
A14: 45115
A15: 45116
A16: 45117
A17: 45118
A18: 45119
... A98: 45199
