Workbook

Sheet 总消费监控
A1: 日期 | B1: feed竞价总消费 | C1: feed竞价企业总消费 | D1: feed竞价企业账户数 | E1: feed企业ARPU | F1: 框架消费 | AE1: Q4feed总消费 | AF1: Q4feed总消费 | AG1: Q4feed总消费
A2: 45108 | B2: =IF(C2="","",C2+F2) -> 361819.13 | C2: =IF(客服部门消费监控!AI3="","",客服部门消费监控!AI3) -> 84046.29 | D2: =IF(客服部门消费监控!AI3="","",客服部门消费监控!AJ3) -> 113 | E2: =IF(客服部门消费监控!AI3="","",客服部门消费监控!AK3) -> 743.77248 | F2: =IF(客服部门消费监控!AI3="","",客服部门消费监控!AC3) -> 277772.84 | H2: 完成分数 | I2: feed总任务 | J2: 昨日总消费 | K2: 剩余天数 | L2: 当前完成率 | M2: 预计可完成 | N2: 预计完成率 | O2: 预计总差额 | P2: 当前日均差额 | Q2: Q3合计消费(扣除罚款） | R2: Q3判罚金额 | S2: Q3总消费 | T2: Q3feed竞价消费 | U2: Q3feedGD消费 | V2: 7月feed竞价消费 | W2: 8月feed竞价消费 | X2: 9月feed竞价消费 | Y2: 时间进度差额 | AE2: 0 | AF2: 0 | AG2: 0
A3: 45109 | B3: =IF(C3="","",C3+F3) -> 402970.17 | C3: =IF(客服部门消费监控!AI4="","",客服部门消费监控!AI4) -> 100818.35 | D3: =IF(客服部门消费监控!AI4="","",客服部门消费监控!AJ4) -> 110 | E3: =IF(客服部门消费监控!AI4="","",客服部门消费监控!AK4) -> 916.53045 | F3: =IF(客服部门消费监控!AI4="","",客服部门消费监控!AC4) -> 302151.82 | H3: 100 | J3: =I12 -> 483199.33 | K3: =92-COUNTIF(C:C,">0") -> 47 | L3: =IF(I3="","",Q3/I3) | M3: =Q3+J3*K3 -> 43419728 | N3: =IF(I3="","",M3/I3) | O3: =IF(I3="","",I3-M3) | P3: =IF(I3="","",O3/K3) | Q3: =S3+R3 -> 20709359 | R3: 0 | S3: =T3+U3 -> 20709359 | T3: =SUM(V3+W3+X3) -> 20709359 | V3: =SUMIFS($B$2:$B$93,$A$2:$A$93,">="&DATE(2023,LEFT(V2,1),1),$A$2:$A$93,"<"&DATE(2023,LEFT(V2,1)+1,1)) -> 13831020 | W3: =SUMIFS($B$2:$B$93,$A$2:$A$93,">="&DATE(2023,LEFT(W2,1),1),$A$2:$A$93,"<"&DATE(2023,LEFT(W2,1)+1,1)) -> 6878338.9 | X3: =SUMIFS($B$2:$B$93,$A$2:$A$93,">="&DATE(2023,LEFT(X2,1),1),$A$2:$A$93,"<"&DATE(2023,LEFT(X2,1)+1,1)) -> 0 | Y3: =(90-K3)/90-L3 -> #VALUE!
A4: 45110 | B4: =IF(C4="","",C4+F4) -> 364224.88 | C4: =IF(客服部门消费监控!AI5="","",客服部门消费监控!AI5) -> 103035.07 | D4: =IF(客服部门消费监控!AI5="","",客服部门消费监控!AJ5) -> 116 | E4: =IF(客服部门消费监控!AI5="","",客服部门消费监控!AK5) -> 888.23336 | F4: =IF(客服部门消费监控!AI5="","",客服部门消费监控!AC5) -> 261189.81
A5: 45111 | B5: =IF(C5="","",C5+F5) -> 404649.01 | C5: =IF(客服部门消费监控!AI6="","",客服部门消费监控!AI6) -> 113684.67 | D5: =IF(客服部门消费监控!AI6="","",客服部门消费监控!AJ6) -> 120 | E5: =IF(客服部门消费监控!AI6="","",客服部门消费监控!AK6) -> 947.37225 | F5: =IF(客服部门消费监控!AI6="","",客服部门消费监控!AC6) -> 290964.34 | H5: 地区 | I5: 昨日feed竞价消费 | J5: 昨日feed竞价账户数 | K5: feed竞价消费环比 | L5: feed竞价户均 | M5: 本月各渠道总消费
A6: 45112 | B6: =IF(C6="","",C6+F6) -> 398218.12 | C6: =IF(客服部门消费监控!AI7="","",客服部门消费监控!AI7) -> 92361.83 | D6: =IF(客服部门消费监控!AI7="","",客服部门消费监控!AJ7) -> 121 | E6: =IF(客服部门消费监控!AI7="","",客服部门消费监控!AK7) -> 763.32091 | F6: =IF(客服部门消费监控!AI7="","",客服部门消费监控!AC7) -> 305856.29 | H6: 厦门 | I6: =OFFSET(分地区消费!$B$3,COUNTIFS(分地区消费!$B$3:$B$94,">=0")-1,0,1,1) -> 147293.18 | J6: =OFFSET(分地区消费!$C$3,COUNTIFS(分地区消费!$C$3:$C$94,">=0")-1,0,1,1) -> 91 | K6: =OFFSET(分地区消费!$B$3,COUNTIFS(分地区消费!$B$3:$B$94,">=0")-1,,1,1)-OFFSET(分地区消费!$B$3,COUNTIFS(分地区消费!$B$3:$B$94,">=0")-2,,1,1) -> -9238.22 | L6: =IF(J6=0,"-",I6/J6) -> 1618.6064 | M6: =SUMIFS(分地区消费!$B$3:$B$94,分地区消费!$A$3:$A$94,">="&DATE(2023,8,1)) -> 1955324.7
A7: 45113 | B7: =IF(C7="","",C7+F7) -> 407759.23 | C7: =IF(客服部门消费监控!AI8="","",客服部门消费监控!AI8) -> 106245.18 | D7: =IF(客服部门消费监控!AI8="","",客服部门消费监控!AJ8) -> 115 | E7: =IF(客服部门消费监控!AI8="","",客服部门消费监控!AK8) -> 923.87113 | F7: =IF(客服部门消费监控!AI8="","",客服部门消费监控!AC8) -> 301514.05 | H7: 泉州 | I7: =OFFSET(分地区消费!$E$3,COUNTIFS(分地区消费!$E$3:$E$94,">=0")-1,0,1,1) -> 21143.17 | J7: =OFFSET(分地区消费!$F$3,COUNTIFS(分地区消费!$F$3:$F$94,">=0")-1,0,1,1) -> 20 | K7: =OFFSET(分地区消费!$E$3,COUNTIFS(分地区消费!$E$3:$E$94,">=0")-1,,1,1)-OFFSET(分地区消费!$E$3,COUNTIFS(分地区消费!$E$3:$E$94,">=0")-2,,1,1) -> -1010.9 | L7: =IF(J7=0,"-",I7/J7) -> 1057.1585 | M7: =SUMIFS(分地区消费!$E$3:$E$94,分地区消费!$A$3:$A$94,">="&DATE(2023,8,1)) -> 329143.65
A8: 45114 | B8: =IF(C8="","",C8+F8) -> 415132.28 | C8: =IF(客服部门消费监控!AI9="","",客服部门消费监控!AI9) -> 98073.38 | D8: =IF(客服部门消费监控!AI9="","",客服部门消费监控!AJ9) -> 116 | E8: =IF(客服部门消费监控!AI9="","",客服部门消费监控!AK9) -> 845.46017 | F8: =IF(客服部门消费监控!AI9="","",客服部门消费监控!AC9) -> 317058.9 | H8: 漳州 | I8: =OFFSET(分地区消费!$H$3,COUNTIFS(分地区消费!$H$3:$H$94,">=0")-1,0,1,1) -> 3185.85 | J8: =OFFSET(分地区消费!$I$3,COUNTIFS(分地区消费!$I$3:$I$94,">0")-1,0,1,1) -> 10 | K8: =OFFSET(分地区消费!$H$3,COUNTIFS(分地区消费!$H$3:$H$94,">0")-1,,1,1)-OFFSET(分地区消费!$H$3,COUNTIFS(分地区消费!$H$3:$H$94,">0")-2,,1,1) -> -2479.69 | L8: =IF(J8=0,"-",I8/J8) -> 318.585 | M8: =SUMIFS(分地区消费!$H$3:$H$94,分地区消费!$A$3:$A$94,">="&DATE(2023,8,1)) -> 42428.3
A9: 45115 | B9: =IF(C9="","",C9+F9) -> 438778.98 | C9: =IF(客服部门消费监控!AI10="","",客服部门消费监控!AI10) -> 115402.89 | D9: =IF(客服部门消费监控!AI10="","",客服部门消费监控!AJ10) -> 106 | E9: =IF(客服部门消费监控!AI10="","",客服部门消费监控!AK10) -> 1088.7065 | F9: =IF(客服部门消费监控!AI10="","",客服部门消费监控!AC10) -> 323376.09 | H9: 龙岩 | I9: =OFFSET(分地区消费!$K$3,COUNTIFS(分地区消费!$K$3:$K$94,">=0")-1,0,1,1) -> 232.92 | J9: =OFFSET(分地区消费!$L$3,COUNTIFS(分地区消费!$L$3:$L$94,">=0")-1,0,1,1) -> 4 | K9: =OFFSET(分地区消费!$K$3,COUNTIFS(分地区消费!$K$3:$K$94,">=0")-1,,1,1)-OFFSET(分地区消费!$K$3,COUNTIFS(分地区消费!$K$3:$K$94,">=0")-2,,1,1) -> 3.87 | L9: =IF(J9=0,"-",I9/J9) -> 58.23 | M9: =SUMIFS(分地区消费!$K$3:$K$94,分地区消费!$A$3:$A$94,">="&DATE(2023,8,1)) -> 1389.99
A10: 45116 | B10: =IF(C10="","",C10+F10) -> 443393.86 | C10: =IF(客服部门消费监控!AI11="","",客服部门消费监控!AI11) -> 119465.71 | D10: =IF(客服部门消费监控!AI11="","",客服部门消费监控!AJ11) -> 108 | E10: =IF(客服部门消费监控!AI11="","",客服部门消费监控!AK11) -> 1106.164 | F10: =IF(客服部门消费监控!AI11="","",客服部门消费监控!AC11) -> 323928.15 | H10: 框架 | I10: =OFFSET(分地区消费!$N$3,COUNTIFS(分地区消费!$N$3:$N$94,">=0")-1,0,1,1) -> 311344.21 | J10: =OFFSET(分地区消费!$O$3,COUNTIFS(分地区消费!$O$3:$O$94,">=0")-1,0,1,1) -> 379 | K10: =OFFSET(分地区消费!$N$3,COUNTIFS(分地区消费!$N$3:$N$94,">=0")-1,,1,1)-OFFSET(分地区消费!$N$3,COUNTIFS(分地区消费!$N$3:$N$94,">=0")-2,,1,1) -> -21283.83 | L10: =IF(J10=0,"-",I10/J10) -> 821.48868 | M10: =SUMIFS(分地区消费!$N$3:$N$94,分地区消费!$A$3:$A$94,">="&DATE(2023,8,1)) -> 4550052.3
A11: 45117 | B11: =IF(C11="","",C11+F11) -> 429982.6 | C11: =IF(客服部门消费监控!AI12="","",客服部门消费监控!AI12) -> 109790.91 | D11: =IF(客服部门消费监控!AI12="","",客服部门消费监控!AJ12) -> 110 | E11: =IF(客服部门消费监控!AI12="","",客服部门消费监控!AK12) -> 998.09918 | F11: =IF(客服部门消费监控!AI12="","",客服部门消费监控!AC12) -> 320191.69 | H11: 其他 | I11: =OFFSET(分地区消费!$Q$3,COUNTIFS(分地区消费!$Q$3:$Q$94,">=0")-1,0,1,1) -> 0 | J11: =OFFSET(分地区消费!$R$3,COUNTIFS(分地区消费!$R$3:$R$94,">=0")-1,0,1,1) -> 0 | K11: =OFFSET(分地区消费!$Q$3,COUNTIFS(分地区消费!$Q$3:$Q$94,">=0")-1,,1,1)-OFFSET(分地区消费!$Q$3,COUNTIFS(分地区消费!$Q$3:$Q$94,">=0")-2,,1,1) -> 0 | L11: =IF(J11=0,"-",I11/J11) -> - | M11: =SUMIFS(分地区消费!$Q$3:$Q$94,分地区消费!$A$3:$A$94,">="&DATE(2023,8,1)) -> 0
A12: 45118 | B12: =IF(C12="","",C12+F12) -> 469684.31 | C12: =IF(客服部门消费监控!AI13="","",客服部门消费监控!AI13) -> 93096.88 | D12: =IF(客服部门消费监控!AI13="","",客服部门消费监控!AJ13) -> 115 | E12: =IF(客服部门消费监控!AI13="","",客服部门消费监控!AK13) -> 809.53809 | F12: =IF(客服部门消费监控!AI13="","",客服部门消费监控!AC13) -> 376587.43 | H12: 总计 | I12: =SUM(I6:I11) -> 483199.33 | J12: =SUM(J6:J11) -> 504 | K12: =SUM(K6:K11) -> -34008.77 | L12: =IF(J12=0,"-",I12/J12) -> 958.72883 | M12: =SUM(M6:M11) -> 6878338.9
A13: 45119 | B13: =IF(C13="","",C13+F13) -> 471175.46 | C13: =IF(客服部门消费监控!AI14="","",客服部门消费监控!AI14) -> 98279.87 | D13: =IF(客服部门消费监控!AI14="","",客服部门消费监控!AJ14) -> 119 | E13: =IF(客服部门消费监控!AI14="","",客服部门消费监控!AK14) -> 825.88126 | F13: =IF(客服部门消费监控!AI14="","",客服部门消费监控!AC14) -> 372895.59
A14: 45120 | B14: =IF(C14="","",C14+F14) -> 426108.76 | C14: =IF(客服部门消费监控!AI15="","",客服部门消费监控!AI15) -> 100544.74 | D14: =IF(客服部门消费监控!AI15="","",客服部门消费监控!AJ15) -> 126 | E14: =IF(客服部门消费监控!AI15="","",客服部门消费监控!AK15) -> 797.97413 | F14: =IF(客服部门消费监控!AI15="","",客服部门消费监控!AC15) -> 325564.02 | H14: 部门 | I14: 昨日feed消费 | J14: 昨日feed竞价账户数 | K14: feed消费环比 | L14: feed户均 | M14: 本月各渠道总消费
A15: 45121 | B15: =IF(C15="","",C15+F15) -> 504612.52 | C15: =IF(客服部门消费监控!AI16="","",客服部门消费监控!AI16) -> 113602.04 | D15: =IF(客服部门消费监控!AI16="","",客服部门消费监控!AJ16) -> 131 | E15: =IF(客服部门消费监控!AI16="","",客服部门消费监控!AK16) -> 867.19115 | F15: =IF(客服部门消费监控!AI16="","",客服部门消费监控!AC16) -> 391010.48 | H15: 大客部门 | I15: =OFFSET(客服部门消费监控!$B$3,COUNTIF(客服部门消费监控!$B$3:$B$94,">=0")-1,0,1,1) -> 140255.07 | J15: =OFFSET(客服部门消费监控!$C$3,COUNTIF(客服部门消费监控!$C$3:$C$94,">=0")-1,0,1,1) -> 54 | K15: =OFFSET(客服部门消费监控!$B$3,COUNTIF(客服部门消费监控!$B$3:$B$94,">=0")-1,,1,1)-OFFSET(客服部门消费监控!$B$3,COUNTIF(客服部门消费监控!$B$3:$B$94,">=0")-2,,1,1) -> -8754.12 | L15: =IFERROR(I15/J15,"-") -> 2597.3161 | M15: =SUMIFS(客服部门消费监控!$B$3:$B$94,客服部门消费监控!$A$3:$A$94,">="&DATE(2023,8,1)) -> 1884498.5
A16: 45122 | B16: =IF(C16="","",C16+F16) -> 497675.1 | C16: =IF(客服部门消费监控!AI17="","",客服部门消费监控!AI17) -> 138517.75 | D16: =IF(客服部门消费监控!AI17="","",客服部门消费监控!AJ17) -> 126 | E16: =IF(客服部门消费监控!AI17="","",客服部门消费监控!AK17) -> 1099.3472 | F16: =IF(客服部门消费监控!AI17="","",客服部门消费监控!AC17) -> 359157.35 | H16: 品牌部 | I16: =OFFSET(客服部门消费监控!$E$3,COUNTIF(客服部门消费监控!$E$3:$E$94,">=0")-1,,1,1) -> 790 | J16: =OFFSET(客服部门消费监控!$F$3,COUNTIFS(客服部门消费监控!$F$3:$F$94,">"&0)-1,0,1,1) -> 4 | K16: =OFFSET(客服部门消费监控!$E$3,COUNTIF(客服部门消费监控!$E$3:$E$94,">=0")-1,,1,1)-OFFSET(客服部门消费监控!$E$3,COUNTIF(客服部门消费监控!$E$3:$E$94,">=0")-2,,1,1) -> 1.65 | L16: =IFERROR(I16/J16,"-") -> 197.5 | M16: =SUMIFS(客服部门消费监控!$E$3:$E$94,客服部门消费监控!$A$3:$A$94,">="&DATE(2023,8,1)) -> 11190.61
A17: 45123 | B17: =IF(C17="","",C17+F17) -> 511026.64 | C17: =IF(客服部门消费监控!AI18="","",客服部门消费监控!AI18) -> 125639.64 | D17: =IF(客服部门消费监控!AI18="","",客服部门消费监控!AJ18) -> 121 | E17: =IF(客服部门消费监控!AI18="","",客服部门消费监控!AK18) -> 1038.3441 | F17: =IF(客服部门消费监控!AI18="","",客服部门消费监控!AC18) -> 385387 | H17: 泉州中小企业增值部 | I17: =OFFSET(客服部门消费监控!$H$3,COUNTIF(客服部门消费监控!$H$3:$H$94,">=0")-1,,1,1) -> 3767.54 | J17: =OFFSET(客服部门消费监控!$I$3,COUNTIF(客服部门消费监控!$I$3:$I$94,">=0")-1,,1,1) -> 9 | K17: =OFFSET(客服部门消费监控!$H$3,COUNTIF(客服部门消费监控!$H$3:$H$94,">=0")-1,,1,1)-OFFSET(客服部门消费监控!$H$3,COUNTIF(客服部门消费监控!$H$3:$H$94,">=0")-2,,1,1) -> -61.47 | L17: =IFERROR(I17/J17,"-") -> 418.61556 | M17: =SUMIFS(客服部门消费监控!$H$3:$H$94,客服部门消费监控!$A$3:$A$94,">="&DATE(2023,8,1)) -> 51487.73
A18: 45124 | B18: =IF(C18="","",C18+F18) -> 428878.14 | C18: =IF(客服部门消费监控!AI19="","",客服部门消费监控!AI19) -> 111396.58 | D18: =IF(客服部门消费监控!AI19="","",客服部门消费监控!AJ19) -> 133 | E18: =IF(客服部门消费监控!AI19="","",客服部门消费监控!AK19) -> 837.56827 | F18: =IF(客服部门消费监控!AI19="","",客服部门消费监控!AC19) -> 317481.56 | H18: 失效挽救部 | I18: =OFFSET(客服部门消费监控!$K$3,COUNTIF(客服部门消费监控!$K$3:$K$94,">=0")-1,,1,1) -> 0 | J18: =OFFSET(客服部门消费监控!$L$3,COUNTIF(客服部门消费监控!$L$3:$L$94,">=0")-1,,1,1) -> 0 | K18: =OFFSET(客服部门消费监控!$K$3,COUNTIF(客服部门消费监控!$K$3:$K$94,">=0")-1,,1,1)-OFFSET(客服部门消费监控!$K$3,COUNTIF(客服部门消费监控!$K$3:$K$94,">=0")-2,,1,1) -> 0 | L18: =IFERROR(I18/J18,"-") -> - | M18: =SUMIFS(客服部门消费监控!$K$3:$K$94,客服部门消费监控!$A$3:$A$94,">="&DATE(2023,8,1)) -> 0
A19: 45125 | B19: =IF(C19="","",C19+F19) -> 461951.99 | C19: =IF(客服部门消费监控!AI20="","",客服部门消费监控!AI20) -> 116229.12 | D19: =IF(客服部门消费监控!AI20="","",客服部门消费监控!AJ20) -> 135 | E19: =IF(客服部门消费监控!AI20="","",客服部门消费监控!AK20) -> 860.95644 | F19: =IF(客服部门消费监控!AI20="","",客服部门消费监控!AC20) -> 345722.87 | H19: 维护部门 | I19: =OFFSET(客服部门消费监控!$N$3,COUNTIF(客服部门消费监控!$N$3:$N$94,">=0")-1,,1,1) -> 198.64 | J19: =OFFSET(客服部门消费监控!$O$3,COUNTIF(客服部门消费监控!$O$3:$O$94,">=0")-1,,1,1) -> 8 | K19: =OFFSET(客服部门消费监控!$N$3,COUNTIF(客服部门消费监控!$N$3:$N$94,">=0")-1,,1,1)-OFFSET(客服部门消费监控!$N$3,COUNTIF(客服部门消费监控!$N$3:$N$94,">=0")-2,,1,1) -> 71.51 | L19: =IFERROR(I19/J19,"-") -> 24.83 | M19: =SUMIFS(客服部门消费监控!$N$3:$N$94,客服部门消费监控!$A$3:$A$94,">="&DATE(2023,8,1)) -> 2876.63
A20: 45126 | B20: =IF(C20="","",C20+F20) -> 459709.91 | C20: =IF(客服部门消费监控!AI21="","",客服部门消费监控!AI21) -> 116370.33 | D20: =IF(客服部门消费监控!AI21="","",客服部门消费监控!AJ21) -> 137 | E20: =IF(客服部门消费监控!AI21="","",客服部门消费监控!AK21) -> 849.41847 | F20: =IF(客服部门消费监控!AI21="","",客服部门消费监控!AC21) -> 343339.58 | H20: 新开部门 | I20: =OFFSET(客服部门消费监控!$Q$3,COUNTIF(客服部门消费监控!$Q$3:$Q$94,">=0")-1,,1,1) -> 182.52 | J20: =OFFSET(客服部门消费监控!$R$3,COUNTIF(客服部门消费监控!$R$3:$R$94,">=0")-1,,1,1) -> 4 | K20: =OFFSET(客服部门消费监控!$Q$3,COUNTIF(客服部门消费监控!$Q$3:$Q$94,">=0")-1,,1,1)-OFFSET(客服部门消费监控!$Q$3,COUNTIF(客服部门消费监控!$Q$3:$Q$94,">=0")-2,,1,1) -> -32.36 | L20: =IFERROR(I20/J20,"-") -> 45.63 | M20: =SUMIFS(客服部门消费监控!$Q$3:$Q$94,客服部门消费监控!$A$3:$A$94,">="&DATE(2023,8,1)) -> 5103.98
A21: 45127 | B21: =IF(C21="","",C21+F21) -> 435978.4 | C21: =IF(客服部门消费监控!AI22="","",客服部门消费监控!AI22) -> 114561.39 | D21: =IF(客服部门消费监控!AI22="","",客服部门消费监控!AJ22) -> 136 | E21: =IF(客服部门消费监控!AI22="","",客服部门消费监控!AK22) -> 842.36316 | F21: =IF(客服部门消费监控!AI22="","",客服部门消费监控!AC22) -> 321417.01 | H21: 行发维护大区 | I21: =OFFSET(客服部门消费监控!$T$3,COUNTIF(客服部门消费监控!$T$3:$T$94,">=0")-1,,1,1) -> 9599.85 | J21: =OFFSET(客服部门消费监控!$U$3,COUNTIF(客服部门消费监控!$U$3:$U$94,">=0")-1,,1,1) -> 24 | K21: =OFFSET(客服部门消费监控!$T$3,COUNTIF(客服部门消费监控!$T$3:$T$94,">=0")-1,,1,1)-OFFSET(客服部门消费监控!$T$3,COUNTIF(客服部门消费监控!$T$3:$T$94,">=0")-2,,1,1) -> -726.78 | L21: =IFERROR(I21/J21,"-") -> 399.99375 | M21: =SUMIFS(客服部门消费监控!$T$3:$T$94,客服部门消费监控!$A$3:$A$94,">="&DATE(2023,8,1)) -> 123462.78
A22: 45128 | B22: =IF(C22="","",C22+F22) -> 416291.11 | C22: =IF(客服部门消费监控!AI23="","",客服部门消费监控!AI23) -> 114137.58 | D22: =IF(客服部门消费监控!AI23="","",客服部门消费监控!AJ23) -> 134 | E22: =IF(客服部门消费监控!AI23="","",客服部门消费监控!AK23) -> 851.77299 | F22: =IF(客服部门消费监控!AI23="","",客服部门消费监控!AC23) -> 302153.53 | H22: 医疗事业部 | I22: =OFFSET(客服部门消费监控!$W$3,COUNTIF(客服部门消费监控!$W$3:$W$94,">=0")-1,,1,1) -> 16342.55 | J22: =OFFSET(客服部门消费监控!$X$3,COUNTIF(客服部门消费监控!$X$3:$X$94,">=0")-1,,1,1) -> 16 | K22: =OFFSET(客服部门消费监控!$W$3,COUNTIF(客服部门消费监控!$W$3:$W$94,">=0")-1,,1,1)-OFFSET(客服部门消费监控!$W$3,COUNTIF(客服部门消费监控!$W$3:$W$94,">=0")-2,,1,1) -> -3543.23 | L22: =IFERROR(I22/J22,"-") -> 1021.4094 | M22: =SUMIFS(客服部门消费监控!$W$3:$W$94,客服部门消费监控!$A$3:$A$94,">="&DATE(2023,8,1)) -> 242915.05
A23: 45129 | B23: =IF(C23="","",C23+F23) -> 461582.63 | C23: =IF(客服部门消费监控!AI24="","",客服部门消费监控!AI24) -> 164422.92 | D23: =IF(客服部门消费监控!AI24="","",客服部门消费监控!AJ24) -> 128 | E23: =IF(客服部门消费监控!AI24="","",客服部门消费监控!AK24) -> 1284.5541 | F23: =IF(客服部门消费监控!AI24="","",客服部门消费监控!AC24) -> 297159.71 | H23: 漳州客服部 | I23: =OFFSET(客服部门消费监控!$Z$3,COUNTIF(客服部门消费监控!$Z$3:$Z$94,">=0")-1,,1,1) -> 718.95 | J23: =OFFSET(客服部门消费监控!$AA$3,COUNTIF(客服部门消费监控!$AA$3:$AA$94,">=0")-1,,1,1) -> 6 | K23: =OFFSET(客服部门消费监控!$Z$3,COUNTIF(客服部门消费监控!$Z$3:$Z$94,">=0")-1,,1,1)-OFFSET(客服部门消费监控!$Z$3,COUNTIF(客服部门消费监控!$Z$3:$Z$94,">=0")-2,,1,1) -> 319.86 | L23: =IFERROR(I23/J23,"-") -> 119.825 | M23: =SUMIFS(客服部门消费监控!$Z$3:$Z$94,客服部门消费监控!$A$3:$A$94,">="&DATE(2023,8,1)) -> 6751.29
A24: 45130 | B24: =IF(C24="","",C24+F24) -> 484191.22 | C24: =IF(客服部门消费监控!AI25="","",客服部门消费监控!AI25) -> 171303.75 | D24: =IF(客服部门消费监控!AI25="","",客服部门消费监控!AJ25) -> 124 | E24: =IF(客服部门消费监控!AI25="","",客服部门消费监控!AK25) -> 1381.4819 | F24: =IF(客服部门消费监控!AI25="","",客服部门消费监控!AC25) -> 312887.47 | H24: 框架 | I24: =OFFSET(客服部门消费监控!$AC$3,COUNTIF(客服部门消费监控!$AC$3:$AC$94,">=0")-1,,1,1) -> 311344.21 | J24: =OFFSET(客服部门消费监控!$AD$3,COUNTIF(客服部门消费监控!$AD$3:$AD$94,">=0")-1,,1,1) -> 379 | K24: =OFFSET(客服部门消费监控!$AC$3,COUNTIF(客服部门消费监控!$AC$3:$AC$94,">=0")-1,,1,1)-OFFSET(客服部门消费监控!$AC$3,COUNTIF(客服部门消费监控!$AC$3:$AC$94,">=0")-2,,1,1) -> -21283.83 | L24: =IFERROR(I24/J24,"-") -> 821.48868 | M24: =SUMIFS(客服部门消费监控!$AC$3:$AC$94,客服部门消费监控!$A$3:$A$94,">="&DATE(2023,8,1)) -> 4550052.3
A25: 45131 | B25: =IF(C25="","",C25+F25) -> 477196.83 | C25: =IF(客服部门消费监控!AI26="","",客服部门消费监控!AI26) -> 171407.12 | D25: =IF(客服部门消费监控!AI26="","",客服部门消费监控!AJ26) -> 134 | E25: =IF(客服部门消费监控!AI26="","",客服部门消费监控!AK26) -> 1279.1576 | F25: =IF(客服部门消费监控!AI26="","",客服部门消费监控!AC26) -> 305789.71 | H25: 运营策略中心 | I25: =OFFSET(客服部门消费监控!$AF$3,COUNTIF(客服部门消费监控!$AF$3:$AF$94,">=0")-1,,1,1) -> 0 | J25: =OFFSET(客服部门消费监控!$AG$3,COUNTIF(客服部门消费监控!$AG$3:$AG$94,">=0")-1,,1,1) -> 0 | K25: =OFFSET(客服部门消费监控!$AF$3,COUNTIF(客服部门消费监控!$AF$3:$AF$94,">=0")-1,,1,1)-OFFSET(客服部门消费监控!$AF$3,COUNTIF(客服部门消费监控!$AF$3:$AF$94,">=0")-2,,1,1) -> 0 | L25: =IFERROR(I25/J25,"-") -> - | M25: =SUMIFS(客服部门消费监控!$AF$3:$AF$94,客服部门消费监控!$A$3:$A$94,">="&DATE(2023,8,1)) -> 0
A26: 45132 | B26: =IF(C26="","",C26+F26) -> 468083.38 | C26: =IF(客服部门消费监控!AI27="","",客服部门消费监控!AI27) -> 160564.96 | D26: =IF(客服部门消费监控!AI27="","",客服部门消费监控!AJ27) -> 134 | E26: =IF(客服部门消费监控!AI27="","",客服部门消费监控!AK27) -> 1198.246 | F26: =IF(客服部门消费监控!AI27="","",客服部门消费监控!AC27) -> 307518.42 | H26: 总计 | I26: =SUM(I15:I25) -> 483199.33 | J26: =SUM(J15:J25) -> 504 | K26: =SUM(K15:K25) -> -34008.77 | L26: =IFERROR(I26/J26,"-") -> 958.72883 | M26: =SUM(M15:M25) -> 6878338.9
A27: 45133 | B27: =IF(C27="","",C27+F27) -> 467702.45 | C27: =IF(客服部门消费监控!AI28="","",客服部门消费监控!AI28) -> 165184.47 | D27: =IF(客服部门消费监控!AI28="","",客服部门消费监控!AJ28) -> 131 | E27: =IF(客服部门消费监控!AI28="","",客服部门消费监控!AK28) -> 1260.9502 | F27: =IF(客服部门消费监控!AI28="","",客服部门消费监控!AC28) -> 302517.98
A28: 45134 | B28: =IF(C28="","",C28+F28) -> 440073.68 | C28: =IF(客服部门消费监控!AI29="","",客服部门消费监控!AI29) -> 137655.61 | D28: =IF(客服部门消费监控!AI29="","",客服部门消费监控!AJ29) -> 131 | E28: =IF(客服部门消费监控!AI29="","",客服部门消费监控!AK29) -> 1050.8062 | F28: =IF(客服部门消费监控!AI29="","",客服部门消费监控!AC29) -> 302418.07
A29: 45135 | B29: =IF(C29="","",C29+F29) -> 493618.74 | C29: =IF(客服部门消费监控!AI30="","",客服部门消费监控!AI30) -> 160799.24 | D29: =IF(客服部门消费监控!AI30="","",客服部门消费监控!AJ30) -> 129 | E29: =IF(客服部门消费监控!AI30="","",客服部门消费监控!AK30) -> 1246.5057 | F29: =IF(客服部门消费监控!AI30="","",客服部门消费监控!AC30) -> 332819.5
A30: 45136 | B30: =IF(C30="","",C30+F30) -> 443236.36 | C30: =IF(客服部门消费监控!AI31="","",客服部门消费监控!AI31) -> 144163.18 | D30: =IF(客服部门消费监控!AI31="","",客服部门消费监控!AJ31) -> 121 | E30: =IF(客服部门消费监控!AI31="","",客服部门消费监控!AK31) -> 1191.4312 | F30: =IF(客服部门消费监控!AI31="","",客服部门消费监控!AC31) -> 299073.18
A31: 45137 | B31: =IF(C31="","",C31+F31) -> 475860.43 | C31: =IF(客服部门消费监控!AI32="","",客服部门消费监控!AI32) -> 175650.79 | D31: =IF(客服部门消费监控!AI32="","",客服部门消费监控!AJ32) -> 120 | E31: =IF(客服部门消费监控!AI32="","",客服部门消费监控!AK32) -> 1463.7566 | F31: =IF(客服部门消费监控!AI32="","",客服部门消费监控!AC32) -> 300209.64
A32: 45138 | B32: =IF(C32="","",C32+F32) -> 469453.92 | C32: =IF(客服部门消费监控!AI33="","",客服部门消费监控!AI33) -> 170857.75 | D32: =IF(客服部门消费监控!AI33="","",客服部门消费监控!AJ33) -> 126 | E32: =IF(客服部门消费监控!AI33="","",客服部门消费监控!AK33) -> 1356.0139 | F32: =IF(客服部门消费监控!AI33="","",客服部门消费监控!AC33) -> 298596.17
A33: 45139 | B33: =IF(C33="","",C33+F33) -> 442608.02 | C33: =IF(客服部门消费监控!AI34="","",客服部门消费监控!AI34) -> 140751.24 | D33: =IF(客服部门消费监控!AI34="","",客服部门消费监控!AJ34) -> 126 | E33: =IF(客服部门消费监控!AI34="","",客服部门消费监控!AK34) -> 1117.0733 | F33: =IF(客服部门消费监控!AI34="","",客服部门消费监控!AC34) -> 301856.78
A34: 45140 | B34: =IF(C34="","",C34+F34) -> 426386.09 | C34: =IF(客服部门消费监控!AI35="","",客服部门消费监控!AI35) -> 141734 | D34: =IF(客服部门消费监控!AI35="","",客服部门消费监控!AJ35) -> 125 | E34: =IF(客服部门消费监控!AI35="","",客服部门消费监控!AK35) -> 1133.872 | F34: =IF(客服部门消费监控!AI35="","",客服部门消费监控!AC35) -> 284652.09
A35: 45141 | B35: =IF(C35="","",C35+F35) -> 422259.8 | C35: =IF(客服部门消费监控!AI36="","",客服部门消费监控!AI36) -> 151992.87 | D35: =IF(客服部门消费监控!AI36="","",客服部门消费监控!AJ36) -> 125 | E35: =IF(客服部门消费监控!AI36="","",客服部门消费监控!AK36) -> 1215.943 | F35: =IF(客服部门消费监控!AI36="","",客服部门消费监控!AC36) -> 270266.93
A36: 45142 | B36: =IF(C36="","",C36+F36) -> 438358.21 | C36: =IF(客服部门消费监控!AI37="","",客服部门消费监控!AI37) -> 148816.07 | D36: =IF(客服部门消费监控!AI37="","",客服部门消费监控!AJ37) -> 121 | E36: =IF(客服部门消费监控!AI37="","",客服部门消费监控!AK37) -> 1229.8849 | F36: =IF(客服部门消费监控!AI37="","",客服部门消费监控!AC37) -> 289542.14
A37: 45143 | B37: =IF(C37="","",C37+F37) -> 515848 | C37: =IF(客服部门消费监控!AI38="","",客服部门消费监控!AI38) -> 160560.16 | D37: =IF(客服部门消费监控!AI38="","",客服部门消费监控!AJ38) -> 117 | E37: =IF(客服部门消费监控!AI38="","",客服部门消费监控!AK38) -> 1372.3091 | F37: =IF(客服部门消费监控!AI38="","",客服部门消费监控!AC38) -> 355287.84
A38: 45144 | B38: =IF(C38="","",C38+F38) -> 533343.11 | C38: =IF(客服部门消费监控!AI39="","",客服部门消费监控!AI39) -> 174276.21 | D38: =IF(客服部门消费监控!AI39="","",客服部门消费监控!AJ39) -> 112 | E38: =IF(客服部门消费监控!AI39="","",客服部门消费监控!AK39) -> 1556.0376 | F38: =IF(客服部门消费监控!AI39="","",客服部门消费监控!AC39) -> 359066.9
... A92: 45198 | B92: =IF(C92="","",C92+F92) | C92: =IF(客服部门消费监控!AI93="","",客服部门消费监控!AI93) | D92: =IF(客服部门消费监控!AI93="","",客服部门消费监控!AJ93) | E92: =IF(客服部门消费监控!AI93="","",客服部门消费监控!AK93) | F92: =IF(客服部门消费监控!AI93="","",客服部门消费监控!AC93)
B93: =IF(C93="","",C93+F93) | C93: =IF(客服部门消费监控!AI94="","",客服部门消费监控!AI94) | D93: =IF(客服部门消费监控!AI94="","",客服部门消费监控!AJ94) | E93: =IF(客服部门消费监控!AI94="","",客服部门消费监控!AK94) | F93: =IF(客服部门消费监控!AI94="","",客服部门消费监控!AC94)

Sheet 消费任务拆解
A1: Feed总消费 | B1: 4月完成 | C1: 5月完成 | D1: 6月目标 | E1: 总完成 | F1: 完成率 | G1: 任务缺口
A2: 3294493 | B2: 173603.11 | C2: 655232.7 | D2: 1000000 | E2: =SUM(B2:D2) -> 1828835.8 | F2: =E2/A2 -> 0.55511905 | G2: =A2-E2 -> 1465657.2
A4: 责任区 | B4: 4月己消费 | C4: 5月当前总消费 | D4: 5月份目标 | E4: 5月剩余任务 | F4: 5月剩余天数 | G4: 5月剩余日均 | H4: 最高日消费 | I4: 现有客户数 | J4: 现有ARPU | K4: 考核方向 | L4: 指标设定
A5: 客服一区 | B5: 66725.29 | C5: 46560 | D5: 448486.1 | E5: 401926.1 | F5: 24 | G5: 16746.921 | H5: 8860.08 | I5: 11 | J5: =H5/I5 -> 805.46182 | K5: 户均提升 大户覆盖 | L5: 消费完成
A6: 大客户部 | B6: 58859.7 | C6: 20239.74 | D6: 194957.95 | E6: 174718.21 | F6: 24 | G6: 7279.9253 | H6: 4443.42 | I6: 13 | J6: =H6/I6 -> 341.80154
A7: 新开部门 | B7: 9397.08 | C7: 2834.31 | D7: 27301.302 | E7: 24466.992 | F7: 24 | G7: 1019.458 | H7: 394.23 | I7: 3 | J7: =H7/I7 -> 131.41 | K7: 新户教育
A8: 客服二区 | B8: 2057.35 | C8: 678.38 | D8: 6534.4501 | E8: 5856.0701 | F8: 24 | G8: 244.00292 | H8: 114.2 | I8: 1 | J8: =H8/I8 -> 114.2 | K8: 客户引入 大户保育 | L8: 10家
A9: 客服三区 | B9: 20497.29 | C9: 240.77 | D9: 4000 | E9: 3759.23 | F9: 24 | G9: 156.63458 | H9: 42.42 | I9: 1 | J9: =H9/I9 -> 42.42 | L9: 5家
A10: 泉州大区 | B10: 5174.29 | C10: 789.14 | D10: 7601.3384 | E10: 6812.1984 | F10: 24 | G10: 283.8416 | H10: 134.14 | I10: 2 | J10: =H10/I10 -> 67.07 | L10: 20家
A11: 漳龙大区 | B11: 2530.85 | C11: 226.42 | D11: 3000 | E11: 2773.58 | F11: 24 | G11: 115.56583 | H11: 50.61 | I11: 1 | J11: =H11/I11 -> 50.61 | L11: 5家
D12: =SUM(D5:D11) -> 691881.13 | E12: =SUM(E5:E11) -> 620312.37 | F12: 24 | G12: =SUM(G5:G11) -> 25846.349
A14: 责任区 | B14: 4月己消费 | C14: 5月己消费 | D14: 6月份目标 | E14: 6月份所需日均 | F14: 考核方向 | G14: 指标设定 | H14: 1，根据目前公司任务要求和进度影响，6月份任务有做调整。请注意。 2，5月9日后由销售方合作的feed新用户不计任务完成。 3，维护大区客户引入以上线消费为准，如暂不能上线的客户不计入任务完成。
A15: 客服一区 | B15: 66725.29 | C15: 379845.23 | D15: 580360.76 | E15: =D15/30 -> 19345.359 | F15: 户均提升 大户覆盖 | G15: 消费完成
A16: 大客户部 | B16: 58859.7 | C16: 167543.94 | D16: 255988.28 | E16: =D16/30 -> 8532.9428
A17: 新开部门 | B17: 9397.08 | C17: 54879.79 | D17: 83850.143 | E17: =D17/30 -> 2795.0048 | F17: 新户教育
A18: 客服二区 | B18: 2057.35 | C18: 15244.97 | D18: 23292.598 | E18: =D18/30 -> 776.41995 | F18: 客户引入 大户保育 | G18: 35家
A19: 客服三区 | B19: 20497.29 | C19: 4407.3 | D19: 6733.8584 | E19: =D19/30 -> 224.46195 | G19: 20家
A20: 泉州大区 | B20: 5174.29 | C20: 24425.13 | D20: 37318.85 | E20: =D20/30 -> 1243.9617 | G20: 35家
A21: 漳龙大区 | B21: 2530.85 | C21: 8152.11 | D21: 12455.507 | E21: =D21/30 -> 415.18355 | G21: 30家
D22: =SUM(D15:D21) -> 1000000 | E22: =D22/30 -> 33333.333

Sheet 客服部门消费监控
A1: 日期 | B1: 大客部门 | E1: 品牌部 | H1: 泉州中小企业增值部 | K1: 失效挽救部 | N1: 维护部门 | Q1: 新开部门 | T1: 行发维护大区 | W1: 医疗事业部 | Z1: 漳州客服部 | AC1: 框架 | AF1: 运营策略中心 | AI1: 企业总计
B2: feed竞价消费 | C2: feed竞价账户数 | D2: feed竞价户均 | E2: feed竞价消费 | F2: feed竞价账户数 | G2: feed竞价户均 | H2: feed竞价消费 | I2: feed竞价账户数 | J2: feed竞价户均 | K2: feed竞价消费 | L2: feed竞价账户数 | M2: feed竞价户均 | N2: feed竞价消费 | O2: feed竞价账户数 | P2: feed竞价户均 | Q2: feed竞价消费 | R2: feed竞价账户数 | S2: feed竞价户均 | T2: feed竞价消费 | U2: feed竞价账户数 | V2: feed竞价户均 | W2: feed竞价消费 | X2: feed竞价账户数 | Y2: feed竞价户均 | Z2: feed竞价消费 | AA2: feed竞价账户数 | AB2: feed竞价户均 | AC2: feed竞价消费 | AD2: feed竞价账户数 | AE2: feed竞价户均 | AF2: feed竞价消费 | AG2: feed竞价账户数 | AH2: feed竞价户均 | AI2: feed竞价总消费 | AJ2: 竞价账户数 | AK2: feed竞价户均
A3: 45108 | B3: 65246.85 | C3: 40 | D3: 1631.1713 | E3: 608.77 | F3: 3 | G3: 202.92333 | H3: 1198.09 | I3: 10 | J3: 119.809 | K3: 0 | L3: 0 | M3: 0 | N3: 92.27 | O3: 3 | P3: 30.756667 | Q3: 493.23 | R3: 7 | S3: 70.461429 | T3: 7422.87 | U3: 31 | V3: 239.44742 | W3: 8832.1 | X3: 14 | Y3: 630.86429 | Z3: 152.11 | AA3: 5 | AB3: 30.422 | AC3: 277772.84 | AD3: 366 | AE3: 758.94219 | AF3: 0 | AG3: 0 | AH3: 0 | AI3: 84046.29 | AJ3: 113 | AK3: 743.77248
A4: 45109 | B4: 80293.99 | C4: 41 | D4: 1958.39 | E4: 644.71 | F4: 3 | G4: 214.90333 | H4: 1285.11 | I4: 9 | J4: 142.79 | K4: 0 | L4: 0 | M4: 0 | N4: 87.99 | O4: 3 | P4: 29.33 | Q4: 313.33 | R4: 6 | S4: 52.221667 | T4: 10019.83 | U4: 30 | V4: 333.99433 | W4: 7972.5 | X4: 13 | Y4: 613.26923 | Z4: 200.89 | AA4: 5 | AB4: 40.178 | AC4: 302151.82 | AD4: 356 | AE4: 848.74107 | AF4: 0 | AG4: 0 | AH4: 0 | AI4: 100818.35 | AJ4: 110 | AK4: 916.53045
A5: 45110 | B5: 86145.07 | C5: 43 | D5: 2003.3737 | E5: 622.61 | F5: 3 | G5: 207.53667 | H5: 1483.15 | I5: 10 | J5: 148.315 | K5: 0 | L5: 0 | M5: 0 | N5: 231.68 | O5: 7 | P5: 33.097143 | Q5: 303.87 | R5: 6 | S5: 50.645 | T5: 7720.89 | U5: 30 | V5: 257.363 | W5: 6346.22 | X5: 12 | Y5: 528.85167 | Z5: 181.58 | AA5: 5 | AB5: 36.316 | AC5: 261189.81 | AD5: 360 | AE5: 725.52725 | AF5: 0 | AG5: 0 | AH5: 0 | AI5: 103035.07 | AJ5: 116 | AK5: 888.23336
A6: 45111 | B6: 96279.98 | C6: 43 | D6: 2239.0693 | E6: 785.35 | F6: 4 | G6: 196.3375 | H6: 1499.22 | I6: 10 | J6: 149.922 | K6: 0 | L6: 0 | M6: 0 | N6: 231.91 | O6: 7 | P6: 33.13 | Q6: 305.36 | R6: 5 | S6: 61.072 | T6: 8170.05 | U6: 33 | V6: 247.57727 | W6: 6197.43 | X6: 13 | Y6: 476.72538 | Z6: 215.37 | AA6: 5 | AB6: 43.074 | AC6: 290964.34 | AD6: 370 | AE6: 786.39011 | AF6: 0 | AG6: 0 | AH6: 0 | AI6: 113684.67 | AJ6: 120 | AK6: 947.37225
A7: 45112 | B7: 75166.53 | C7: 45 | D7: 1670.3673 | E7: 788.93 | F7: 4 | G7: 197.2325 | H7: 1239.5 | I7: 11 | J7: 112.68182 | K7: 0 | L7: 0 | M7: 0 | N7: 263.5 | O7: 7 | P7: 37.642857 | Q7: 214.07 | R7: 6 | S7: 35.678333 | T7: 7718.91 | U7: 31 | V7: 248.9971 | W7: 6726.17 | X7: 12 | Y7: 560.51417 | Z7: 244.22 | AA7: 5 | AB7: 48.844 | AC7: 305856.29 | AD7: 383 | AE7: 798.58039 | AF7: 0 | AG7: 0 | AH7: 0 | AI7: 92361.83 | AJ7: 121 | AK7: 763.32091
A8: 45113 | B8: 89634.36 | C8: 43 | D8: 2084.52 | E8: 797.87 | F8: 4 | G8: 199.4675 | H8: 1262.7 | I8: 10 | J8: 126.27 | K8: 0 | L8: 0 | M8: 0 | N8: 261.9 | O8: 7 | P8: 37.414286 | Q8: 196.67 | R8: 5 | S8: 39.334 | T8: 7297.23 | U8: 28 | V8: 260.61536 | W8: 6487.19 | X8: 13 | Y8: 499.01462 | Z8: 307.26 | AA8: 5 | AB8: 61.452 | AC8: 301514.05 | AD8: 381 | AE8: 791.37546 | AF8: 0 | AG8: 0 | AH8: 0 | AI8: 106245.18 | AJ8: 115 | AK8: 923.87113
A9: 45114 | B9: 80988.82 | C9: 42 | D9: 1928.3052 | E9: 819.64 | F9: 4 | G9: 204.91 | H9: 2007.12 | I9: 10 | J9: 200.712 | K9: 0 | L9: 0 | M9: 0 | N9: 253.12 | O9: 7 | P9: 36.16 | Q9: 56.34 | R9: 5 | S9: 11.268 | T9: 6605.42 | U9: 30 | V9: 220.18067 | W9: 7104.87 | X9: 13 | Y9: 546.52846 | Z9: 238.05 | AA9: 5 | AB9: 47.61 | AC9: 317058.9 | AD9: 375 | AE9: 845.4904 | AF9: 0 | AG9: 0 | AH9: 0 | AI9: 98073.38 | AJ9: 116 | AK9: 845.46017
A10: 45115 | B10: 101014.46 | C10: 42 | D10: 2405.1062 | E10: 820.65 | F10: 4 | G10: 205.1625 | H10: 1516.72 | I10: 10 | J10: 151.672 | K10: 0 | L10: 0 | M10: 0 | N10: 99.79 | O10: 3 | P10: 33.263333 | Q10: 78.32 | R10: 4 | S10: 19.58 | T10: 6293.73 | U10: 26 | V10: 242.06654 | W10: 5267.81 | X10: 12 | Y10: 438.98417 | Z10: 311.41 | AA10: 5 | AB10: 62.282 | AC10: 323376.09 | AD10: 387 | AE10: 835.59713 | AF10: 0 | AG10: 0 | AH10: 0 | AI10: 115402.89 | AJ10: 106 | AK10: 1088.7065
A11: 45116 | B11: 106133.96 | C11: 41 | D11: 2588.6332 | E11: 799.09 | F11: 4 | G11: 199.7725 | H11: 1366.49 | I11: 10 | J11: 136.649 | K11: 0 | L11: 0 | M11: 0 | N11: 105.34 | O11: 3 | P11: 35.113333 | Q11: 25.9 | R11: 5 | S11: 5.18 | T11: 4894.69 | U11: 28 | V11: 174.81036 | W11: 5897.98 | X11: 12 | Y11: 491.49833 | Z11: 242.26 | AA11: 5 | AB11: 48.452 | AC11: 323928.15 | AD11: 373 | AE11: 868.44008 | AF11: 0 | AG11: 0 | AH11: 0 | AI11: 119465.71 | AJ11: 108 | AK11: 1106.164
A12: 45117 | B12: 95816.72 | C12: 43 | D12: 2228.2958 | E12: 781.53 | F12: 4 | G12: 195.3825 | H12: 1111.33 | I12: 9 | J12: 123.48111 | K12: 0 | L12: 0 | M12: 0 | N12: 266.81 | O12: 9 | P12: 29.645556 | Q12: 13.75 | R12: 4 | S12: 3.4375 | T12: 5051.82 | U12: 24 | V12: 210.4925 | W12: 6531.51 | X12: 12 | Y12: 544.2925 | Z12: 217.44 | AA12: 5 | AB12: 43.488 | AC12: 320191.69 | AD12: 396 | AE12: 808.56487 | AF12: 0 | AG12: 0 | AH12: 0 | AI12: 109790.91 | AJ12: 110 | AK12: 998.09918
A13: 45118 | B13: 77936.61 | C13: 45 | D13: 1731.9247 | E13: 781.85 | F13: 4 | G13: 195.4625 | H13: 657.26 | I13: 9 | J13: 73.028889 | K13: 0 | L13: 0 | M13: 0 | N13: 279.52 | O13: 8 | P13: 34.94 | Q13: 12.18 | R13: 3 | S13: 4.06 | T13: 6214.77 | U13: 27 | V13: 230.17667 | W13: 7005.91 | X13: 14 | Y13: 500.42214 | Z13: 208.78 | AA13: 5 | AB13: 41.756 | AC13: 376587.43 | AD13: 395 | AE13: 953.3859 | AF13: 0 | AG13: 0 | AH13: 0 | AI13: 93096.88 | AJ13: 115 | AK13: 809.53809
A14: 45119 | B14: 81291.77 | C14: 45 | D14: 1806.4838 | E14: 827.45 | F14: 4 | G14: 206.8625 | H14: 712.31 | I14: 10 | J14: 71.231 | K14: 0 | L14: 0 | M14: 0 | N14: 299.41 | O14: 8 | P14: 37.42625 | Q14: 10.92 | R14: 3 | S14: 3.64 | T14: 7771.13 | U14: 29 | V14: 267.97 | W14: 7143.02 | X14: 15 | Y14: 476.20133 | Z14: 223.86 | AA14: 5 | AB14: 44.772 | AC14: 372895.59 | AD14: 395 | AE14: 944.03947 | AF14: 0 | AG14: 0 | AH14: 0 | AI14: 98279.87 | AJ14: 119 | AK14: 825.88126
... A20: 45125 | B20: 88554.71 | C20: 51 | D20: 1736.3669 | E20: 808.04 | F20: 4 | G20: 202.01 | H20: 1961.23 | I20: 11 | J20: 178.29364 | K20: 0 | L20: 0 | M20: 0 | N20: 324.64 | O20: 9 | P20: 36.071111 | Q20: 1801.81 | R20: 6 | S20: 300.30167 | T20: 9557.48 | U20: 32 | V20: 298.67125 | W20: 12114.17 | X20: 15 | Y20: 807.61133 | Z20: 1107.04 | AA20: 7 | AB20: 158.14857 | AC20: 345722.87 | AD20: 400 | AE20: 864.30718 | AF20: 0 | AG20: 0 | AH20: 0 | AI20: 116229.12 | AJ20: 135 | AK20: 860.95644
A21: 45126 | B21: 84054.67 | C21: 51 | D21: 1648.1308 | E21: 799.62 | F21: 4 | G21: 199.905 | H21: 2064.41 | I21: 11 | J21: 187.67364 | K21: 0 | L21: 0 | M21: 0 | N21: 289.1 | O21: 9 | P21: 32.122222 | Q21: 1826.86 | R21: 6 | S21: 304.47667 | T21: 13661.05 | U21: 33 | V21: 413.97121 | W21: 12653.11 | X21: 16 | Y21: 790.81938 | Z21: 1021.51 | AA21: 7 | AB21: 145.93 | AC21: 343339.58 | AD21: 390 | AE21: 880.3579 | AF21: 0 | AG21: 0 | AH21: 0 | AI21: 116370.33 | AJ21: 137 | AK21: 849.41847
A22: 45127 | B22: 81939.93 | C22: 51 | D22: 1606.6653 | E22: 760.36 | F22: 4 | G22: 190.09 | H22: 2458.51 | I22: 10 | J22: 245.851 | K22: 0 | L22: 0 | M22: 0 | N22: 331.52 | O22: 9 | P22: 36.835556 | Q22: 2223.61 | R22: 6 | S22: 370.60167 | T22: 10514.66 | U22: 32 | V22: 328.58312 | W22: 15257.88 | X22: 17 | Y22: 897.52235 | Z22: 1074.92 | AA22: 7 | AB22: 153.56 | AC22: 321417.01 | AD22: 389 | AE22: 826.26481 | AF22: 0 | AG22: 0 | AH22: 0 | AI22: 114561.39 | AJ22: 136 | AK22: 842.36316
A23: 45128 | B23: 81577 | C23: 50 | D23: 1631.54 | E23: 634.56 | F23: 3 | G23: 211.52 | H23: 3074.54 | I23: 11 | J23: 279.50364 | K23: 0 | L23: 0 | M23: 0 | N23: 333.04 | O23: 9 | P23: 37.004444 | Q23: 2271.69 | R23: 6 | S23: 378.615 | T23: 8977.5 | U23: 31 | V23: 289.59677 | W23: 16212.16 | X23: 17 | Y23: 953.65647 | Z23: 1057.09 | AA23: 7 | AB23: 151.01286 | AC23: 302153.53 | AD23: 389 | AE23: 776.74429 | AF23: 0 | AG23: 0 | AH23: 0 | AI23: 114137.58 | AJ23: 134 | AK23: 851.77299
A24: 45129 | B24: 131104.05 | C24: 49 | D24: 2675.5929 | E24: 802.11 | F24: 4 | G24: 200.5275 | H24: 2475.91 | I24: 11 | J24: 225.08273 | K24: 0 | L24: 0 | M24: 0 | N24: 170.32 | O24: 5 | P24: 34.064 | Q24: 1944.52 | R24: 6 | S24: 324.08667 | T24: 9137.06 | U24: 29 | V24: 315.07103 | W24: 18388.02 | X24: 17 | Y24: 1081.6482 | Z24: 400.93 | AA24: 7 | AB24: 57.275714 | AC24: 297159.71 | AD24: 362 | AE24: 820.88318 | AF24: 0 | AG24: 0 | AH24: 0 | AI24: 164422.92 | AJ24: 128 | AK24: 1284.5541
A25: 45130 | B25: 141195.98 | C25: 48 | D25: 2941.5829 | E25: 808.7 | F25: 4 | G25: 202.175 | H25: 2486.51 | I25: 11 | J25: 226.04636 | K25: 0 | L25: 0 | M25: 0 | N25: 189.28 | O25: 5 | P25: 37.856 | Q25: 795.13 | R25: 7 | S25: 113.59 | T25: 9406.33 | U25: 26 | V25: 361.78192 | W25: 16020.21 | X25: 17 | Y25: 942.36529 | Z25: 401.61 | AA25: 6 | AB25: 66.935 | AC25: 312887.47 | AD25: 349 | AE25: 896.5257 | AF25: 0 | AG25: 0 | AH25: 0 | AI25: 171303.75 | AJ25: 124 | AK25: 1381.4819
A26: 45131 | B26: 132915.68 | C26: 50 | D26: 2658.3136 | E26: 798.58 | F26: 4 | G26: 199.645 | H26: 2843.61 | I26: 11 | J26: 258.51 | K26: 0 | L26: 0 | M26: 0 | N26: 339.14 | O26: 10 | P26: 33.914 | Q26: 1391.68 | R26: 6 | S26: 231.94667 | T26: 16042.08 | U26: 30 | V26: 534.736 | W26: 16651.75 | X26: 17 | Y26: 979.51471 | Z26: 424.6 | AA26: 6 | AB26: 70.766667 | AC26: 305789.71 | AD26: 361 | AE26: 847.06291 | AF26: 0 | AG26: 0 | AH26: 0 | AI26: 171407.12 | AJ26: 134 | AK26: 1279.1576
A27: 45132 | B27: 127928.46 | C27: 48 | D27: 2665.1762 | E27: 836.52 | F27: 4 | G27: 209.13 | H27: 2444.99 | I27: 11 | J27: 222.27182 | K27: 0 | L27: 0 | M27: 0 | N27: 325.62 | O27: 10 | P27: 32.562 | Q27: 1944.49 | R27: 8 | S27: 243.06125 | T27: 10400.64 | U27: 30 | V27: 346.688 | W27: 16327.52 | X27: 17 | Y27: 960.44235 | Z27: 356.72 | AA27: 6 | AB27: 59.453333 | AC27: 307518.42 | AD27: 357 | AE27: 861.39613 | AF27: 0 | AG27: 0 | AH27: 0 | AI27: 160564.96 | AJ27: 134 | AK27: 1198.246
A28: 45133 | B28: 132605.7 | C28: 49 | D28: 2706.2388 | E28: 820.73 | F28: 4 | G28: 205.1825 | H28: 2624.73 | I28: 11 | J28: 238.61182 | K28: 0 | L28: 0 | M28: 0 | N28: 284.75 | O28: 9 | P28: 31.638889 | Q28: 1540.58 | R28: 8 | S28: 192.5725 | T28: 12011.37 | U28: 28 | V28: 428.9775 | W28: 14840.43 | X28: 16 | Y28: 927.52688 | Z28: 456.18 | AA28: 6 | AB28: 76.03 | AC28: 302517.98 | AD28: 355 | AE28: 852.16332 | AF28: 0 | AG28: 0 | AH28: 0 | AI28: 165184.47 | AJ28: 131 | AK28: 1260.9502
A29: 45134 | B29: 109554.47 | C29: 52 | D29: 2106.8167 | E29: 788 | F29: 4 | G29: 197 | H29: 2899.57 | I29: 11 | J29: 263.59727 | K29: 0 | L29: 0 | M29: 0 | N29: 287.83 | O29: 9 | P29: 31.981111 | Q29: 1578.53 | R29: 6 | S29: 263.08833 | T29: 8780.73 | U29: 27 | V29: 325.21222 | W29: 13363.69 | X29: 16 | Y29: 835.23063 | Z29: 402.79 | AA29: 6 | AB29: 67.131667 | AC29: 302418.07 | AD29: 369 | AE29: 819.56117 | AF29: 0 | AG29: 0 | AH29: 0 | AI29: 137655.61 | AJ29: 131 | AK29: 1050.8062
A30: 45135 | B30: 133876.48 | C30: 51 | D30: 2625.029 | E30: 801.6 | F30: 4 | G30: 200.4 | H30: 2392.07 | I30: 11 | J30: 217.46091 | K30: 0 | L30: 0 | M30: 0 | N30: 372.87 | O30: 9 | P30: 41.43 | Q30: 1172.78 | R30: 7 | S30: 167.54 | T30: 8373.04 | U30: 27 | V30: 310.11259 | W30: 13441.8 | X30: 15 | Y30: 896.12 | Z30: 368.6 | AA30: 5 | AB30: 73.72 | AC30: 332819.5 | AD30: 378 | AE30: 880.47487 | AF30: 0 | AG30: 0 | AH30: 0 | AI30: 160799.24 | AJ30: 129 | AK30: 1246.5057
A31: 45136 | B31: 115633.17 | C31: 49 | D31: 2359.8606 | E31: 817.88 | F31: 4 | G31: 204.47 | H31: 2392.5 | I31: 11 | J31: 217.5 | K31: 0 | L31: 0 | M31: 0 | N31: 154.87 | O31: 6 | P31: 25.811667 | Q31: 1970.24 | R31: 6 | S31: 328.37333 | T31: 8273.13 | U31: 25 | V31: 330.9252 | W31: 14668.15 | X31: 15 | Y31: 977.87667 | Z31: 253.24 | AA31: 5 | AB31: 50.648 | AC31: 299073.18 | AD31: 332 | AE31: 900.82283 | AF31: 0 | AG31: 0 | AH31: 0 | AI31: 144163.18 | AJ31: 121 | AK31: 1191.4312
A32: 45137 | B32: 148193.06 | C32: 47 | D32: 3153.0438 | E32: 795.41 | F32: 4 | G32: 198.8525 | H32: 2516.13 | I32: 11 | J32: 228.73909 | K32: 0 | L32: 0 | M32: 0 | N32: 189.38 | O32: 5 | P32: 37.876 | Q32: 1994.15 | R32: 7 | S32: 284.87857 | T32: 8673.21 | U32: 25 | V32: 346.9284 | W32: 13054.56 | X32: 16 | Y32: 815.91 | Z32: 234.89 | AA32: 5 | AB32: 46.978 | AC32: 300209.64 | AD32: 335 | AE32: 896.14818 | AF32: 0 | AG32: 0 | AH32: 0 | AI32: 175650.79 | AJ32: 120 | AK32: 1463.7566
A33: 45138 | B33: 140903.27 | C33: 48 | D33: 2935.4848 | E33: 800.86 | F33: 4 | G33: 200.215 | H33: 2949.94 | I33: 11 | J33: 268.17636 | K33: 0 | L33: 0 | M33: 0 | N33: 325.76 | O33: 10 | P33: 32.576 | Q33: 1607.48 | R33: 7 | S33: 229.64 | T33: 8575.43 | U33: 25 | V33: 343.0172 | W33: 15513.64 | X33: 16 | Y33: 969.6025 | Z33: 181.37 | AA33: 5 | AB33: 36.274 | AC33: 298596.17 | AD33: 338 | AE33: 883.42062 | AF33: 0 | AG33: 0 | AH33: 0 | AI33: 170857.75 | AJ33: 126 | AK33: 1356.0139
A34: 45139 | B34: 110282.46 | C34: 49 | D34: 2250.6624 | E34: 820.51 | F34: 4 | G34: 205.1275 | H34: 3604.7 | I34: 10 | J34: 360.47 | K34: 0 | L34: 0 | M34: 0 | N34: 342.04 | O34: 9 | P34: 38.004444 | Q34: 2189.26 | R34: 8 | S34: 273.6575 | T34: 7510.82 | U34: 26 | V34: 288.87769 | W34: 15834.58 | X34: 15 | Y34: 1055.6387 | Z34: 166.87 | AA34: 5 | AB34: 33.374 | AC34: 301856.78 | AD34: 338 | AE34: 893.0674 | AF34: 0 | AG34: 0 | AH34: 0 | AI34: 140751.24 | AJ34: 126 | AK34: 1117.0733
A35: 45140 | B35: 114093.74 | C35: 53 | D35: 2152.7121 | E35: 793.18 | F35: 4 | G35: 198.295 | H35: 4120.49 | I35: 10 | J35: 412.049 | K35: 0 | L35: 0 | M35: 0 | N35: 224.23 | O35: 8 | P35: 28.02875 | Q35: 283.61 | R35: 5 | S35: 56.722 | T35: 7915.16 | U35: 27 | V35: 293.15407 | W35: 13814.37 | X35: 13 | Y35: 1062.6438 | Z35: 489.22 | AA35: 5 | AB35: 97.844 | AC35: 284652.09 | AD35: 344 | AE35: 827.47701 | AF35: 0 | AG35: 0 | AH35: 0 | AI35: 141734 | AJ35: 125 | AK35: 1133.872
A36: 45141 | B36: 118836.91 | C36: 54 | D36: 2200.6835 | E36: 787.15 | F36: 4 | G36: 196.7875 | H36: 3819.71 | I36: 10 | J36: 381.971 | K36: 0 | L36: 0 | M36: 0 | N36: 241.89 | O36: 8 | P36: 30.23625 | Q36: 282.83 | R36: 3 | S36: 94.276667 | T36: 10544.13 | U36: 27 | V36: 390.52333 | W36: 16776.71 | X36: 14 | Y36: 1198.3364 | Z36: 703.54 | AA36: 5 | AB36: 140.708 | AC36: 270266.93 | AD36: 342 | AE36: 790.25418 | AF36: 0 | AG36: 0 | AH36: 0 | AI36: 151992.87 | AJ36: 125 | AK36: 1215.943
A37: 45142 | B37: 119757.13 | C37: 53 | D37: 2259.5685 | E37: 804.53 | F37: 4 | G37: 201.1325 | H37: 3511.72 | I37: 8 | J37: 438.965 | K37: 0 | L37: 0 | M37: 0 | N37: 238.56 | O37: 8 | P37: 29.82 | Q37: 205.26 | R37: 3 | S37: 68.42 | T37: 8251.22 | U37: 27 | V37: 305.60074 | W37: 15279.36 | X37: 13 | Y37: 1175.3354 | Z37: 768.29 | AA37: 5 | AB37: 153.658 | AC37: 289542.14 | AD37: 353 | AE37: 820.23269 | AF37: 0 | AG37: 0 | AH37: 0 | AI37: 148816.07 | AJ37: 121 | AK37: 1229.8849
A38: 45143 | B38: 129137.86 | C38: 50 | D38: 2582.7572 | E38: 826.97 | F38: 4 | G38: 206.7425 | H38: 3536.44 | I38: 9 | J38: 392.93778 | K38: 0 | L38: 0 | M38: 0 | N38: 129.82 | O38: 5 | P38: 25.964 | Q38: 214.85 | R38: 4 | S38: 53.7125 | T38: 9316.19 | U38: 26 | V38: 358.315 | W38: 16615.89 | X38: 13 | Y38: 1278.1454 | Z38: 782.14 | AA38: 6 | AB38: 130.35667 | AC38: 355287.84 | AD38: 347 | AE38: 1023.8843 | AF38: 0 | AG38: 0 | AH38: 0 | AI38: 160560.16 | AJ38: 117 | AK38: 1372.3091
A39: 45144 | B39: 141125.34 | C39: 48 | D39: 2940.1112 | E39: 805.84 | F39: 4 | G39: 201.46 | H39: 3503.13 | I39: 10 | J39: 350.313 | K39: 0 | L39: 0 | M39: 0 | N39: 107.91 | O39: 4 | P39: 26.9775 | Q39: 312.81 | R39: 4 | S39: 78.2025 | T39: 10952.96 | U39: 25 | V39: 438.1184 | W39: 17327.78 | X39: 13 | Y39: 1332.9062 | Z39: 140.44 | AA39: 4 | AB39: 35.11 | AC39: 359066.9 | AD39: 336 | AE39: 1068.6515 | AF39: 0 | AG39: 0 | AH39: 0 | AI39: 174276.21 | AJ39: 112 | AK39: 1556.0376
A40: 45145 | B40: 121936.47 | C40: 55 | D40: 2217.0267 | E40: 795.38 | F40: 4 | G40: 198.845 | H40: 2688.07 | I40: 9 | J40: 298.67444 | K40: 0 | L40: 0 | M40: 0 | N40: 262.07 | O40: 9 | P40: 29.118889 | Q40: 235.31 | R40: 4 | S40: 58.8275 | T40: 8199.22 | U40: 25 | V40: 327.9688 | W40: 14831.43 | X40: 14 | Y40: 1059.3879 | Z40: 140.3 | AA40: 4 | AB40: 35.075 | AC40: 344545.47 | AD40: 356 | AE40: 967.82435 | AF40: 0 | AG40: 0 | AH40: 0 | AI40: 149088.25 | AJ40: 124 | AK40: 1202.3246
A41: 45146 | B41: 117713.9 | C41: 56 | D41: 2102.0339 | E41: 799.27 | F41: 4 | G41: 199.8175 | H41: 3229.53 | I41: 8 | J41: 403.69125 | K41: 0 | L41: 0 | M41: 0 | N41: 225.38 | O41: 8 | P41: 28.1725 | Q41: 182.73 | R41: 3 | S41: 60.91 | T41: 7344.12 | U41: 24 | V41: 306.005 | W41: 16334.63 | X41: 14 | Y41: 1166.7593 | Z41: 243.65 | AA41: 5 | AB41: 48.73 | AC41: 317150.34 | AD41: 364 | AE41: 871.29214 | AF41: 0 | AG41: 0 | AH41: 0 | AI41: 146073.21 | AJ41: 122 | AK41: 1197.3214
A42: 45147 | B42: 123261.89 | C42: 56 | D42: 2201.1052 | E42: 794.88 | F42: 4 | G42: 198.72 | H42: 3899.06 | I42: 8 | J42: 487.3825 | K42: 0 | L42: 0 | M42: 0 | N42: 229.58 | O42: 9 | P42: 25.508889 | Q42: 191.24 | R42: 3 | S42: 63.746667 | T42: 8698.42 | U42: 24 | V42: 362.43417 | W42: 20173.51 | X42: 14 | Y42: 1440.965 | Z42: 207.56 | AA42: 5 | AB42: 41.512 | AC42: 325059.71 | AD42: 369 | AE42: 880.92062 | AF42: 0 | AG42: 0 | AH42: 0 | AI42: 157456.14 | AJ42: 123 | AK42: 1280.1312
A43: 45148 | B43: 145381.08 | C43: 56 | D43: 2596.0907 | E43: 788.58 | F43: 4 | G43: 197.145 | H43: 4100.76 | I43: 9 | J43: 455.64 | K43: 0 | L43: 0 | M43: 0 | N43: 222.85 | O43: 8 | P43: 27.85625 | Q43: 181.67 | R43: 3 | S43: 60.556667 | T43: 8602.71 | U43: 24 | V43: 358.44625 | W43: 20625.66 | X43: 16 | Y43: 1289.1037 | Z43: 311.64 | AA43: 6 | AB43: 51.94 | AC43: 324895.57 | AD43: 376 | AE43: 864.08396 | AF43: 0 | AG43: 0 | AH43: 0 | AI43: 180214.95 | AJ43: 126 | AK43: 1430.2774
A44: 45149 | B44: 174865.67 | C44: 55 | D44: 3179.3758 | E44: 778.31 | F44: 4 | G44: 194.5775 | H44: 3997.59 | I44: 9 | J44: 444.17667 | K44: 0 | L44: 0 | M44: 0 | N44: 219.79 | O44: 8 | P44: 27.47375 | Q44: 220.77 | R44: 4 | S44: 55.1925 | T44: 7756.18 | U44: 24 | V44: 323.17417 | W44: 19969.58 | X44: 16 | Y44: 1248.0988 | Z44: 887.92 | AA44: 6 | AB44: 147.98667 | AC44: 361294.62 | AD44: 398 | AE44: 907.77543 | AF44: 0 | AG44: 0 | AH44: 0 | AI44: 208695.81 | AJ44: 126 | AK44: 1656.316
A45: 45150 | B45: 178841.83 | C45: 51 | D45: 3506.7025 | E45: 817.66 | F45: 4 | G45: 204.415 | H45: 3879.98 | I45: 9 | J45: 431.10889 | K45: 0 | L45: 0 | M45: 0 | N45: 106.74 | O45: 4 | P45: 26.685 | Q45: 206.24 | R45: 5 | S45: 41.248 | T45: 8445.17 | U45: 23 | V45: 367.1813 | W45: 19103.22 | X45: 16 | Y45: 1193.9513 | Z45: 791.68 | AA45: 6 | AB45: 131.94667 | AC45: 372461.65 | AD45: 382 | AE45: 975.0305 | AF45: 0 | AG45: 0 | AH45: 0 | AI45: 212192.52 | AJ45: 118 | AK45: 1798.2417
...

Sheet 分地区消费
A1: 日期 | B1: 厦门市 | E1: 泉州市 | H1: 漳州市 | K1: 龙岩市 | N1: 框架 | Q1: 其他市 | T1: 企业总计
B2: feed竞价消费 | C2: feed竞价账户数 | D2: feed竞价户均 | E2: feed竞价消费 | F2: feed竞价账户数 | G2: feed竞价户均 | H2: feed竞价消费 | I2: feed竞价账户数 | J2: feed竞价户均 | K2: feed竞价消费 | L2: feed竞价账户数 | M2: feed竞价户均 | N2: feed竞价消费 | O2: feed竞价账户数 | P2: feed竞价户均 | Q2: feed竞价消费 | R2: feed竞价账户数 | S2: feed竞价户均 | T2: 企业总消费 | U2: feed竞价账户数 | V2: feed竞价户均
A3: 45108 | B3: 80010.2 | C3: 87 | D3: 919.65747 | E3: 3673.32 | F3: 15 | G3: 244.888 | H3: 152.11 | I3: 5 | J3: 30.422 | K3: 210.66 | L3: 6 | M3: 35.11 | N3: 277772.84 | O3: 366 | P3: 758.94219 | Q3: 0 | R3: 0 | S3: 0 | T3: 84046.29 | U3: 113 | V3: 743.77248
A4: 45109 | B4: 94614.57 | C4: 84 | D4: 1126.3639 | E4: 4794.58 | F4: 14 | G4: 342.47 | H4: 1233.03 | I4: 7 | J4: 176.14714 | K4: 176.17 | L4: 5 | M4: 35.234 | N4: 302151.82 | O4: 356 | P4: 848.74107 | Q4: 0 | R4: 0 | S4: 0 | T4: 100818.35 | U4: 110 | V4: 916.53045
A5: 45110 | B5: 95616.77 | C5: 88 | D5: 1086.5542 | E5: 3271.52 | F5: 15 | G5: 218.10133 | H5: 3922.17 | I5: 7 | J5: 560.31 | K5: 224.61 | L5: 6 | M5: 37.435 | N5: 261189.81 | O5: 360 | P5: 725.52725 | Q5: 0 | R5: 0 | S5: 0 | T5: 103035.07 | U5: 116 | V5: 888.23336
A6: 45111 | B6: 109691.13 | C6: 91 | D6: 1205.397 | E6: 3448.53 | F6: 16 | G6: 215.53313 | H6: 277.25 | I6: 6 | J6: 46.208333 | K6: 267.76 | L6: 7 | M6: 38.251429 | N6: 290964.34 | O6: 370 | P6: 786.39011 | Q6: 0 | R6: 0 | S6: 0 | T6: 113684.67 | U6: 120 | V6: 947.37225
A7: 45112 | B7: 88225.71 | C7: 92 | D7: 958.97511 | E7: 3634.53 | F7: 16 | G7: 227.15813 | H7: 285.81 | I7: 6 | J7: 47.635 | K7: 215.78 | L7: 7 | M7: 30.825714 | N7: 305856.29 | O7: 383 | P7: 798.58039 | Q7: 0 | R7: 0 | S7: 0 | T7: 92361.83 | U7: 121 | V7: 763.32091
A8: 45113 | B8: 102357.2 | C8: 89 | D8: 1150.0809 | E8: 3114.63 | F8: 15 | G8: 207.642 | H8: 624.33 | I8: 6 | J8: 104.055 | K8: 149.02 | L8: 5 | M8: 29.804 | N8: 301514.05 | O8: 381 | P8: 791.37546 | Q8: 0 | R8: 0 | S8: 0 | T8: 106245.18 | U8: 115 | V8: 923.87113
A9: 45114 | B9: 92394.1 | C9: 90 | D9: 1026.6011 | E9: 4990.91 | F9: 15 | G9: 332.72733 | H9: 638.99 | I9: 6 | J9: 106.49833 | K9: 49.38 | L9: 5 | M9: 9.876 | N9: 317058.9 | O9: 375 | P9: 845.4904 | Q9: 0 | R9: 0 | S9: 0 | T9: 98073.38 | U9: 116 | V9: 845.46017
A10: 45115 | B10: 111420.48 | C10: 82 | D10: 1358.7863 | E10: 3397.74 | F10: 15 | G10: 226.516 | H10: 439.47 | I10: 6 | J10: 73.245 | K10: 145.2 | L10: 3 | M10: 48.4 | N10: 323376.09 | O10: 387 | P10: 835.59713 | Q10: 0 | R10: 0 | S10: 0 | T10: 115402.89 | U10: 106 | V10: 1088.7065
A11: 45116 | B11: 115244.57 | C11: 84 | D11: 1371.9592 | E11: 3568.06 | F11: 15 | G11: 237.87067 | H11: 502 | I11: 6 | J11: 83.666667 | K11: 151.08 | L11: 3 | M11: 50.36 | N11: 323928.15 | O11: 373 | P11: 868.44008 | Q11: 0 | R11: 0 | S11: 0 | T11: 119465.71 | U11: 108 | V11: 1106.164
A12: 45117 | B12: 105183.8 | C12: 86 | D12: 1223.0674 | E12: 4216.96 | F12: 14 | G12: 301.21143 | H12: 235.99 | I12: 6 | J12: 39.331667 | K12: 154.16 | L12: 4 | M12: 38.54 | N12: 320191.69 | O12: 396 | P12: 808.56487 | Q12: 0 | R12: 0 | S12: 0 | T12: 109790.91 | U12: 110 | V12: 998.09918
A13: 45118 | B13: 88864.78 | C13: 90 | D13: 987.38644 | E13: 3490.53 | F13: 14 | G13: 249.32357 | H13: 550.16 | I13: 6 | J13: 91.693333 | K13: 191.41 | L13: 5 | M13: 38.282 | N13: 376587.43 | O13: 395 | P13: 953.3859 | Q13: 0 | R13: 0 | S13: 0 | T13: 93096.88 | U13: 115 | V13: 809.53809
A14: 45119 | B14: 94567.32 | C14: 91 | D14: 1039.2013 | E14: 3109.64 | F14: 17 | G14: 182.92 | H14: 409.69 | I14: 6 | J14: 68.281667 | K14: 193.22 | L14: 5 | M14: 38.644 | N14: 372895.59 | O14: 395 | P14: 944.03947 | Q14: 0 | R14: 0 | S14: 0 | T14: 98279.87 | U14: 119 | V14: 825.88126
... A20: 45125 | B20: 106649.3 | C20: 99 | D20: 1077.2657 | E20: 4892.99 | F20: 20 | G20: 244.6495 | H20: 4499.94 | I20: 10 | J20: 449.994 | K20: 186.89 | L20: 6 | M20: 31.148333 | N20: 345722.87 | O20: 400 | P20: 864.30718 | Q20: 0 | R20: 0 | S20: 0 | T20: 116229.12 | U20: 135 | V20: 860.95644
A21: 45126 | B21: 106181.07 | C21: 100 | D21: 1061.8107 | E21: 5760.69 | F21: 19 | G21: 303.19421 | H21: 4279.96 | I21: 12 | J21: 356.66333 | K21: 148.61 | L21: 6 | M21: 24.768333 | N21: 343339.58 | O21: 390 | P21: 880.3579 | Q21: 0 | R21: 0 | S21: 0 | T21: 116370.33 | U21: 137 | V21: 849.41847
A22: 45127 | B22: 102550.97 | C22: 99 | D22: 1035.8684 | E22: 6787.64 | F22: 19 | G22: 357.24421 | H22: 5034.84 | I22: 12 | J22: 419.57 | K22: 187.94 | L22: 6 | M22: 31.323333 | N22: 321417.01 | O22: 389 | P22: 826.26481 | Q22: 0 | R22: 0 | S22: 0 | T22: 114561.39 | U22: 136 | V22: 842.36316
A23: 45128 | B23: 103915.06 | C23: 98 | D23: 1060.3578 | E23: 7721.48 | F23: 20 | G23: 386.074 | H23: 2344.8 | I23: 10 | J23: 234.48 | K23: 156.24 | L23: 6 | M23: 26.04 | N23: 302153.53 | O23: 389 | P23: 776.74429 | Q23: 0 | R23: 0 | S23: 0 | T23: 114137.58 | U23: 134 | V23: 851.77299
A24: 45129 | B24: 155428.88 | C24: 93 | D24: 1671.2783 | E24: 6761.94 | F24: 20 | G24: 338.097 | H24: 2028.49 | I24: 10 | J24: 202.849 | K24: 203.61 | L24: 5 | M24: 40.722 | N24: 297159.71 | O24: 362 | P24: 820.88318 | Q24: 0 | R24: 0 | S24: 0 | T24: 164422.92 | U24: 128 | V24: 1284.5541
A25: 45130 | B25: 163088.38 | C25: 91 | D25: 1792.18 | E25: 6659.67 | F25: 19 | G25: 350.50895 | H25: 1366.23 | I25: 9 | J25: 151.80333 | K25: 189.47 | L25: 5 | M25: 37.894 | N25: 312887.47 | O25: 349 | P25: 896.5257 | Q25: 0 | R25: 0 | S25: 0 | T25: 171303.75 | U25: 124 | V25: 1381.4819
A26: 45131 | B26: 163477.28 | C26: 100 | D26: 1634.7728 | E26: 6309.5 | F26: 19 | G26: 332.07895 | H26: 1182.65 | I26: 9 | J26: 131.40556 | K26: 437.69 | L26: 6 | M26: 72.948333 | N26: 305789.71 | O26: 361 | P26: 847.06291 | Q26: 0 | R26: 0 | S26: 0 | T26: 171407.12 | U26: 134 | V26: 1279.1576
A27: 45132 | B27: 151834.55 | C27: 100 | D27: 1518.3455 | E27: 6536.08 | F27: 19 | G27: 344.00421 | H27: 1790.58 | I27: 9 | J27: 198.95333 | K27: 403.75 | L27: 6 | M27: 67.291667 | N27: 307518.42 | O27: 357 | P27: 861.39613 | Q27: 0 | R27: 0 | S27: 0 | T27: 160564.96 | U27: 134 | V27: 1198.246
A28: 45133 | B28: 156985.16 | C28: 98 | D28: 1601.8894 | E28: 6231.81 | F28: 19 | G28: 327.99 | H28: 1676.87 | I28: 9 | J28: 186.31889 | K28: 290.63 | L28: 5 | M28: 58.126 | N28: 302517.98 | O28: 355 | P28: 852.16332 | Q28: 0 | R28: 0 | S28: 0 | T28: 165184.47 | U28: 131 | V28: 1260.9502
A29: 45134 | B29: 129289.99 | C29: 97 | D29: 1332.8865 | E29: 5801.18 | F29: 19 | G29: 305.32526 | H29: 2260.61 | I29: 10 | J29: 226.061 | K29: 303.83 | L29: 5 | M29: 60.766 | N29: 302418.07 | O29: 369 | P29: 819.56117 | Q29: 0 | R29: 0 | S29: 0 | T29: 137655.61 | U29: 131 | V29: 1050.8062
A30: 45135 | B30: 153731.73 | C30: 96 | D30: 1601.3722 | E30: 5090.06 | F30: 19 | G30: 267.89789 | H30: 1668.82 | I30: 9 | J30: 185.42444 | K30: 308.63 | L30: 5 | M30: 61.726 | N30: 332819.5 | O30: 378 | P30: 880.47487 | Q30: 0 | R30: 0 | S30: 0 | T30: 160799.24 | U30: 129 | V30: 1246.5057
A31: 45136 | B31: 135804.1 | C31: 90 | D31: 1508.9344 | E31: 6336.5 | F31: 19 | G31: 333.5 | H31: 1636.35 | I31: 8 | J31: 204.54375 | K31: 386.23 | L31: 4 | M31: 96.5575 | N31: 299073.18 | O31: 332 | P31: 900.82283 | Q31: 0 | R31: 0 | S31: 0 | T31: 144163.18 | U31: 121 | V31: 1191.4312
A32: 45137 | B32: 167371.67 | C32: 89 | D32: 1880.5806 | E32: 5902.13 | F32: 19 | G32: 310.63842 | H32: 2067.91 | I32: 8 | J32: 258.48875 | K32: 309.08 | L32: 4 | M32: 77.27 | N32: 300209.64 | O32: 335 | P32: 896.14818 | Q32: 0 | R32: 0 | S32: 0 | T32: 175650.79 | U32: 120 | V32: 1463.7566
A33: 45138 | B33: 162541.49 | C33: 94 | D33: 1729.1648 | E33: 6012.47 | F33: 19 | G33: 316.44579 | H33: 2000.72 | I33: 8 | J33: 250.09 | K33: 303.07 | L33: 5 | M33: 60.614 | N33: 298596.17 | O33: 338 | P33: 883.42062 | Q33: 0 | R33: 0 | S33: 0 | T33: 170857.75 | U33: 126 | V33: 1356.0139
A34: 45139 | B34: 132607.22 | C34: 96 | D34: 1381.3252 | E34: 6645.66 | F34: 18 | G34: 369.20333 | H34: 1254.91 | I34: 7 | J34: 179.27286 | K34: 243.45 | L34: 5 | M34: 48.69 | N34: 301856.78 | O34: 338 | P34: 893.0674 | Q34: 0 | R34: 0 | S34: 0 | T34: 140751.24 | U34: 126 | V34: 1117.0733
A35: 45140 | B35: 131738.4 | C35: 96 | D35: 1372.275 | E35: 7944.89 | F35: 18 | G35: 441.38278 | H35: 2013.33 | I35: 7 | J35: 287.61857 | K35: 37.38 | L35: 4 | M35: 9.345 | N35: 284652.09 | O35: 344 | P35: 827.47701 | Q35: 0 | R35: 0 | S35: 0 | T35: 141734 | U35: 125 | V35: 1133.872
A36: 45141 | B36: 140013.69 | C36: 95 | D36: 1473.8283 | E36: 10339.24 | F36: 19 | G36: 544.17053 | H36: 1594.61 | I36: 7 | J36: 227.80143 | K36: 45.33 | L36: 4 | M36: 11.3325 | N36: 270266.93 | O36: 342 | P36: 790.25418 | Q36: 0 | R36: 0 | S36: 0 | T36: 151992.87 | U36: 125 | V36: 1215.943
A37: 45142 | B37: 127174.57 | C37: 94 | D37: 1352.921 | E37: 20392.14 | F37: 17 | G37: 1199.5376 | H37: 1199.78 | I37: 6 | J37: 199.96333 | K37: 49.58 | L37: 4 | M37: 12.395 | N37: 289542.14 | O37: 353 | P37: 820.23269 | Q37: 0 | R37: 0 | S37: 0 | T37: 148816.07 | U37: 121 | V37: 1229.8849
A38: 45143 | B38: 125846.56 | C38: 89 | D38: 1414.0063 | E38: 33286.14 | F38: 18 | G38: 1849.23 | H38: 1382.54 | I38: 7 | J38: 197.50571 | K38: 44.92 | L38: 3 | M38: 14.973333 | N38: 355287.84 | O38: 347 | P38: 1023.8843 | Q38: 0 | R38: 0 | S38: 0 | T38: 160560.16 | U38: 117 | V38: 1372.3091
A39: 45144 | B39: 137124.14 | C39: 85 | D39: 1613.2252 | E39: 35906.12 | F39: 19 | G39: 1889.7958 | H39: 1196.41 | I39: 5 | J39: 239.282 | K39: 49.54 | L39: 3 | M39: 16.513333 | N39: 359066.9 | O39: 336 | P39: 1068.6515 | Q39: 0 | R39: 0 | S39: 0 | T39: 174276.21 | U39: 112 | V39: 1556.0376
A40: 45145 | B40: 121983.79 | C40: 94 | D40: 1297.6999 | E40: 25465.41 | F40: 19 | G40: 1340.2847 | H40: 1581.89 | I40: 7 | J40: 225.98429 | K40: 57.16 | L40: 4 | M40: 14.29 | N40: 344545.47 | O40: 356 | P40: 967.82435 | Q40: 0 | R40: 0 | S40: 0 | T40: 149088.25 | U40: 124 | V40: 1202.3246
A41: 45146 | B41: 120613.72 | C41: 91 | D41: 1325.4255 | E41: 24065.9 | F41: 19 | G41: 1266.6263 | H41: 1313.11 | I41: 8 | J41: 164.13875 | K41: 80.48 | L41: 4 | M41: 20.12 | N41: 317150.34 | O41: 364 | P41: 871.29214 | Q41: 0 | R41: 0 | S41: 0 | T41: 146073.21 | U41: 122 | V41: 1197.3214
A42: 45147 | B42: 125053.42 | C42: 92 | D42: 1359.2763 | E42: 30242.7 | F42: 19 | G42: 1591.7211 | H42: 2094.84 | I42: 8 | J42: 261.855 | K42: 65.18 | L42: 4 | M42: 16.295 | N42: 325059.71 | O42: 369 | P42: 880.92062 | Q42: 0 | R42: 0 | S42: 0 | T42: 157456.14 | U42: 123 | V42: 1280.1312
A43: 45148 | B43: 152341.24 | C43: 91 | D43: 1674.0796 | E43: 22985.36 | F43: 21 | G43: 1094.541 | H43: 4792.61 | I43: 10 | J43: 479.261 | K43: 95.74 | L43: 4 | M43: 23.935 | N43: 324895.57 | O43: 376 | P43: 864.08396 | Q43: 0 | R43: 0 | S43: 0 | T43: 180214.95 | U43: 126 | V43: 1430.2774
A44: 45149 | B44: 165413.72 | C44: 91 | D44: 1817.7332 | E44: 35567.62 | F44: 21 | G44: 1693.6962 | H44: 7672.1 | I44: 10 | J44: 767.21 | K44: 42.37 | L44: 4 | M44: 10.5925 | N44: 361294.62 | O44: 398 | P44: 907.77543 | Q44: 0 | R44: 0 | S44: 0 | T44: 208695.81 | U44: 126 | V44: 1656.316
A45: 45150 | B45: 171589.62 | C45: 85 | D45: 2018.7014 | E45: 33005.23 | F45: 20 | G45: 1650.2615 | H45: 7480.78 | I45: 10 | J45: 748.078 | K45: 116.89 | L45: 3 | M45: 38.963333 | N45: 372461.65 | O45: 382 | P45: 975.0305 | Q45: 0 | R45: 0 | S45: 0 | T45: 212192.52 | U45: 118 | V45: 1798.2417
...
